Workbook

Sheet Сводная
A1: Сова · Сводная по всем направлениям
A2: ="Все кабинеты VK Реклама клиники · данные по "&TEXT($E$3,"DD.MM.YYYY")
A3: Все направления | D3: Данные по | E3: ='⚙ Настройки'!$B$7 | G3: Период с | I3: по | N3: 📈 Подписки и расход по неделям и месяцам (завершённые периоды)
H4: =IF(AND(ISNUMBER(H3),ISNUMBER(J3),H3>J3),"⚠ Дата «с» позже даты «по»",IF(OR(ISNUMBER(H3),ISNUMBER(J3)),"Сравнение — с предыдущим периодом той же длины. Очистите поля, чтобы вернуть текущий месяц.","Пусто — текущий месяц. Дату выбирают двойным щелчком."))
A5: =IF(OR(ISNUMBER($H$3),ISNUMBER($J$3)),"Выбранный период против предыдущего той же длины","Этот месяц против тех же дней прошлого")
A6: Период | B6: Расход | C6: Расход с НДС | D6: Показы | E6: Клики | F6: CTR | G6: CPC | H6: Подписки | I6: Цена подписки | J6: CR в подписку | K6: с | L6: по
A7: =IF(OR(ISNUMBER($H$3),ISNUMBER($J$3)),"Выбранный период","Этот месяц") | B7: =SUMIFS('Данные'!$C:$C,'Данные'!$A:$A,">="&$K$7,'Данные'!$A:$A,"<"&$L$7+1) | C7: =B7*(100+22)/100 | D7: =SUMIFS('Данные'!$D:$D,'Данные'!$A:$A,">="&$K$7,'Данные'!$A:$A,"<"&$L$7+1) | E7: =SUMIFS('Данные'!$E:$E,'Данные'!$A:$A,">="&$K$7,'Данные'!$A:$A,"<"&$L$7+1) | F7: =IFERROR(E7/D7,"") | G7: =IFERROR(B7/E7,"") | H7: =SUMIFS('Данные'!$F:$F,'Данные'!$A:$A,">="&$K$7,'Данные'!$A:$A,"<"&$L$7+1) | I7: =IFERROR(B7/H7,"") | J7: =IFERROR(H7/E7,"") | K7: =IF(ISNUMBER($H$3),$H$3,DATE(YEAR(L7),MONTH(L7),1)) | L7: =IF(ISNUMBER($J$3),$J$3,$E$3)
A8: =IF(OR(ISNUMBER($H$3),ISNUMBER($J$3)),"Предыдущий, той же длины","Прошлый, те же дни") | B8: =SUMIFS('Данные'!$C:$C,'Данные'!$A:$A,">="&$K$8,'Данные'!$A:$A,"<"&$L$8+1) | C8: =B8*(100+22)/100 | D8: =SUMIFS('Данные'!$D:$D,'Данные'!$A:$A,">="&$K$8,'Данные'!$A:$A,"<"&$L$8+1) | E8: =SUMIFS('Данные'!$E:$E,'Данные'!$A:$A,">="&$K$8,'Данные'!$A:$A,"<"&$L$8+1) | F8: =IFERROR(E8/D8,"") | G8: =IFERROR(B8/E8,"") | H8: =SUMIFS('Данные'!$F:$F,'Данные'!$A:$A,">="&$K$8,'Данные'!$A:$A,"<"&$L$8+1) | I8: =IFERROR(B8/H8,"") | J8: =IFERROR(H8/E8,"") | K8: =IF(OR(ISNUMBER($H$3),ISNUMBER($J$3)),2*K7-L7-1,EDATE(K7,-1)) | L8: =IF(OR(ISNUMBER($H$3),ISNUMBER($J$3)),K7-1,EDATE(L7,-1))
A9: Изменение | B9: =IFERROR(B7/B8-1,"") | C9: =IFERROR(C7/C8-1,"") | D9: =IFERROR(D7/D8-1,"") | E9: =IFERROR(E7/E8-1,"") | F9: =IFERROR(F7/F8-1,"") | G9: =IFERROR(G7/G8-1,"") | H9: =IFERROR(H7/H8-1,"") | I9: =IFERROR(I7/I8-1,"") | J9: =IFERROR(J7/J8-1,"")
A11: ="🏥 Направления за "&TEXT($K$7,"DD.MM.YYYY")&" — "&TEXT($L$7,"DD.MM.YYYY")&" (те же даты, что выше)"
A12: Направление | B12: Расход | C12: Расход с НДС | D12: Показы | E12: Клики | F12: CTR | G12: CPC | H12: Подписки | I12: Цена подписки | J12: CR в подписку | K12: Доля расхода
A13: ='⚙ Настройки'!$A$2 | B13: =SUMIFS('Данные'!$C:$C,'Данные'!$A:$A,">="&$K$7,'Данные'!$A:$A,"<"&$L$7+1,'Данные'!$B:$B,$A13) | C13: =B13*(100+22)/100 | D13: =SUMIFS('Данные'!$D:$D,'Данные'!$A:$A,">="&$K$7,'Данные'!$A:$A,"<"&$L$7+1,'Данные'!$B:$B,$A13) | E13: =SUMIFS('Данные'!$E:$E,'Данные'!$A:$A,">="&$K$7,'Данные'!$A:$A,"<"&$L$7+1,'Данные'!$B:$B,$A13) | F13: =IFERROR(E13/D13,"") | G13: =IFERROR(B13/E13,"") | H13: =SUMIFS('Данные'!$F:$F,'Данные'!$A:$A,">="&$K$7,'Данные'!$A:$A,"<"&$L$7+1,'Данные'!$B:$B,$A13) | I13: =IFERROR(B13/H13,"") | J13: =IFERROR(H13/E13,"") | K13: =IFERROR(B13/$B$16,"")
A14: ='⚙ Настройки'!$A$3 | B14: =SUMIFS('Данные'!$C:$C,'Данные'!$A:$A,">="&$K$7,'Данные'!$A:$A,"<"&$L$7+1,'Данные'!$B:$B,$A14) | C14: =B14*(100+22)/100 | D14: =SUMIFS('Данные'!$D:$D,'Данные'!$A:$A,">="&$K$7,'Данные'!$A:$A,"<"&$L$7+1,'Данные'!$B:$B,$A14) | E14: =SUMIFS('Данные'!$E:$E,'Данные'!$A:$A,">="&$K$7,'Данные'!$A:$A,"<"&$L$7+1,'Данные'!$B:$B,$A14) | F14: =IFERROR(E14/D14,"") | G14: =IFERROR(B14/E14,"") | H14: =SUMIFS('Данные'!$F:$F,'Данные'!$A:$A,">="&$K$7,'Данные'!$A:$A,"<"&$L$7+1,'Данные'!$B:$B,$A14) | I14: =IFERROR(B14/H14,"") | J14: =IFERROR(H14/E14,"") | K14: =IFERROR(B14/$B$16,"")
A15: ='⚙ Настройки'!$A$4 | B15: =SUMIFS('Данные'!$C:$C,'Данные'!$A:$A,">="&$K$7,'Данные'!$A:$A,"<"&$L$7+1,'Данные'!$B:$B,$A15) | C15: =B15*(100+22)/100 | D15: =SUMIFS('Данные'!$D:$D,'Данные'!$A:$A,">="&$K$7,'Данные'!$A:$A,"<"&$L$7+1,'Данные'!$B:$B,$A15) | E15: =SUMIFS('Данные'!$E:$E,'Данные'!$A:$A,">="&$K$7,'Данные'!$A:$A,"<"&$L$7+1,'Данные'!$B:$B,$A15) | F15: =IFERROR(E15/D15,"") | G15: =IFERROR(B15/E15,"") | H15: =SUMIFS('Данные'!$F:$F,'Данные'!$A:$A,">="&$K$7,'Данные'!$A:$A,"<"&$L$7+1,'Данные'!$B:$B,$A15) | I15: =IFERROR(B15/H15,"") | J15: =IFERROR(H15/E15,"") | K15: =IFERROR(B15/$B$16,"")
A16: Итого | B16: =SUM(B13:B15) | C16: =B16*(100+22)/100 | D16: =SUM(D13:D15) | E16: =SUM(E13:E15) | F16: =IFERROR(E16/D16,"") | G16: =IFERROR(B16/E16,"") | H16: =SUM(H13:H15) | I16: =IFERROR(B16/H16,"") | J16: =IFERROR(H16/E16,"") | K16: =IFERROR(B16/$B$16,"")
A18: 🧭 Подписки по направлениям, по неделям | D18: Тенденция: | E18: =IFERROR(SLOPE(E20:E45,{1;2;3;4;5;6;7;8;9;10;11;12;13;14;15;16;17;18;19;20;21;22;23;24;25;26})/AVERAGE(E20:E45),"") | F18: в неделю
A19: Неделя | B19: ='⚙ Настройки'!$A$2 | C19: ='⚙ Настройки'!$A$3 | D19: ='⚙ Настройки'!$A$4 | E19: Итого | F19: К прошлой
A20: =TEXT((($E$3-WEEKDAY($E$3,2)+1-7*(WEEKDAY($E$3,2)<7))-7*25),"DD.MM")&"–"&TEXT((($E$3-WEEKDAY($E$3,2)+1-7*(WEEKDAY($E$3,2)<7))-7*25)+6,"DD.MM.YYYY") | B20: =SUMIFS('Данные'!$F:$F,'Данные'!$A:$A,">="&(($E$3-WEEKDAY($E$3,2)+1-7*(WEEKDAY($E$3,2)<7))-7*25),'Данные'!$A:$A,"<"&((($E$3-WEEKDAY($E$3,2)+1-7*(WEEKDAY($E$3,2)<7))-7*25)+6)+1,'Данные'!$B:$B,B$19) | C20: =SUMIFS('Данные'!$F:$F,'Данные'!$A:$A,">="&(($E$3-WEEKDAY($E$3,2)+1-7*(WEEKDAY($E$3,2)<7))-7*25),'Данные'!$A:$A,"<"&((($E$3-WEEKDAY($E$3,2)+1-7*(WEEKDAY($E$3,2)<7))-7*25)+6)+1,'Данные'!$B:$B,C$19) | D20: =SUMIFS('Данные'!$F:$F,'Данные'!$A:$A,">="&(($E$3-WEEKDAY($E$3,2)+1-7*(WEEKDAY($E$3,2)<7))-7*25),'Данные'!$A:$A,"<"&((($E$3-WEEKDAY($E$3,2)+1-7*(WEEKDAY($E$3,2)<7))-7*25)+6)+1,'Данные'!$B:$B,D$19) | E20: =SUM(B20:D20)
A21: =TEXT((($E$3-WEEKDAY($E$3,2)+1-7*(WEEKDAY($E$3,2)<7))-7*24),"DD.MM")&"–"&TEXT((($E$3-WEEKDAY($E$3,2)+1-7*(WEEKDAY($E$3,2)<7))-7*24)+6,"DD.MM.YYYY") | B21: =SUMIFS('Данные'!$F:$F,'Данные'!$A:$A,">="&(($E$3-WEEKDAY($E$3,2)+1-7*(WEEKDAY($E$3,2)<7))-7*24),'Данные'!$A:$A,"<"&((($E$3-WEEKDAY($E$3,2)+1-7*(WEEKDAY($E$3,2)<7))-7*24)+6)+1,'Данные'!$B:$B,B$19) | C21: =SUMIFS('Данные'!$F:$F,'Данные'!$A:$A,">="&(($E$3-WEEKDAY($E$3,2)+1-7*(WEEKDAY($E$3,2)<7))-7*24),'Данные'!$A:$A,"<"&((($E$3-WEEKDAY($E$3,2)+1-7*(WEEKDAY($E$3,2)<7))-7*24)+6)+1,'Данные'!$B:$B,C$19) | D21: =SUMIFS('Данные'!$F:$F,'Данные'!$A:$A,">="&(($E$3-WEEKDAY($E$3,2)+1-7*(WEEKDAY($E$3,2)<7))-7*24),'Данные'!$A:$A,"<"&((($E$3-WEEKDAY($E$3,2)+1-7*(WEEKDAY($E$3,2)<7))-7*24)+6)+1,'Данные'!$B:$B,D$19) | E21: =SUM(B21:D21) | F21: =IFERROR(E21/E20-1,"")
A22: =TEXT((($E$3-WEEKDAY($E$3,2)+1-7*(WEEKDAY($E$3,2)<7))-7*23),"DD.MM")&"–"&TEXT((($E$3-WEEKDAY($E$3,2)+1-7*(WEEKDAY($E$3,2)<7))-7*23)+6,"DD.MM.YYYY") | B22: =SUMIFS('Данные'!$F:$F,'Данные'!$A:$A,">="&(($E$3-WEEKDAY($E$3,2)+1-7*(WEEKDAY($E$3,2)<7))-7*23),'Данные'!$A:$A,"<"&((($E$3-WEEKDAY($E$3,2)+1-7*(WEEKDAY($E$3,2)<7))-7*23)+6)+1,'Данные'!$B:$B,B$19) | C22: =SUMIFS('Данные'!$F:$F,'Данные'!$A:$A,">="&(($E$3-WEEKDAY($E$3,2)+1-7*(WEEKDAY($E$3,2)<7))-7*23),'Данные'!$A:$A,"<"&((($E$3-WEEKDAY($E$3,2)+1-7*(WEEKDAY($E$3,2)<7))-7*23)+6)+1,'Данные'!$B:$B,C$19) | D22: =SUMIFS('Данные'!$F:$F,'Данные'!$A:$A,">="&(($E$3-WEEKDAY($E$3,2)+1-7*(WEEKDAY($E$3,2)<7))-7*23),'Данные'!$A:$A,"<"&((($E$3-WEEKDAY($E$3,2)+1-7*(WEEKDAY($E$3,2)<7))-7*23)+6)+1,'Данные'!$B:$B,D$19) | E22: =SUM(B22:D22) | F22: =IFERROR(E22/E21-1,"")
A23: =TEXT((($E$3-WEEKDAY($E$3,2)+1-7*(WEEKDAY($E$3,2)<7))-7*22),"DD.MM")&"–"&TEXT((($E$3-WEEKDAY($E$3,2)+1-7*(WEEKDAY($E$3,2)<7))-7*22)+6,"DD.MM.YYYY") | B23: =SUMIFS('Данные'!$F:$F,'Данные'!$A:$A,">="&(($E$3-WEEKDAY($E$3,2)+1-7*(WEEKDAY($E$3,2)<7))-7*22),'Данные'!$A:$A,"<"&((($E$3-WEEKDAY($E$3,2)+1-7*(WEEKDAY($E$3,2)<7))-7*22)+6)+1,'Данные'!$B:$B,B$19) | C23: =SUMIFS('Данные'!$F:$F,'Данные'!$A:$A,">="&(($E$3-WEEKDAY($E$3,2)+1-7*(WEEKDAY($E$3,2)<7))-7*22),'Данные'!$A:$A,"<"&((($E$3-WEEKDAY($E$3,2)+1-7*(WEEKDAY($E$3,2)<7))-7*22)+6)+1,'Данные'!$B:$B,C$19) | D23: =SUMIFS('Данные'!$F:$F,'Данные'!$A:$A,">="&(($E$3-WEEKDAY($E$3,2)+1-7*(WEEKDAY($E$3,2)<7))-7*22),'Данные'!$A:$A,"<"&((($E$3-WEEKDAY($E$3,2)+1-7*(WEEKDAY($E$3,2)<7))-7*22)+6)+1,'Данные'!$B:$B,D$19) | E23: =SUM(B23:D23) | F23: =IFERROR(E23/E22-1,"")
A24: =TEXT((($E$3-WEEKDAY($E$3,2)+1-7*(WEEKDAY($E$3,2)<7))-7*21),"DD.MM")&"–"&TEXT((($E$3-WEEKDAY($E$3,2)+1-7*(WEEKDAY($E$3,2)<7))-7*21)+6,"DD.MM.YYYY") | B24: =SUMIFS('Данные'!$F:$F,'Данные'!$A:$A,">="&(($E$3-WEEKDAY($E$3,2)+1-7*(WEEKDAY($E$3,2)<7))-7*21),'Данные'!$A:$A,"<"&((($E$3-WEEKDAY($E$3,2)+1-7*(WEEKDAY($E$3,2)<7))-7*21)+6)+1,'Данные'!$B:$B,B$19) | C24: =SUMIFS('Данные'!$F:$F,'Данные'!$A:$A,">="&(($E$3-WEEKDAY($E$3,2)+1-7*(WEEKDAY($E$3,2)<7))-7*21),'Данные'!$A:$A,"<"&((($E$3-WEEKDAY($E$3,2)+1-7*(WEEKDAY($E$3,2)<7))-7*21)+6)+1,'Данные'!$B:$B,C$19) | D24: =SUMIFS('Данные'!$F:$F,'Данные'!$A:$A,">="&(($E$3-WEEKDAY($E$3,2)+1-7*(WEEKDAY($E$3,2)<7))-7*21),'Данные'!$A:$A,"<"&((($E$3-WEEKDAY($E$3,2)+1-7*(WEEKDAY($E$3,2)<7))-7*21)+6)+1,'Данные'!$B:$B,D$19) | E24: =SUM(B24:D24) | F24: =IFERROR(E24/E23-1,"")
A25: =TEXT((($E$3-WEEKDAY($E$3,2)+1-7*(WEEKDAY($E$3,2)<7))-7*20),"DD.MM")&"–"&TEXT((($E$3-WEEKDAY($E$3,2)+1-7*(WEEKDAY($E$3,2)<7))-7*20)+6,"DD.MM.YYYY") | B25: =SUMIFS('Данные'!$F:$F,'Данные'!$A:$A,">="&(($E$3-WEEKDAY($E$3,2)+1-7*(WEEKDAY($E$3,2)<7))-7*20),'Данные'!$A:$A,"<"&((($E$3-WEEKDAY($E$3,2)+1-7*(WEEKDAY($E$3,2)<7))-7*20)+6)+1,'Данные'!$B:$B,B$19) | C25: =SUMIFS('Данные'!$F:$F,'Данные'!$A:$A,">="&(($E$3-WEEKDAY($E$3,2)+1-7*(WEEKDAY($E$3,2)<7))-7*20),'Данные'!$A:$A,"<"&((($E$3-WEEKDAY($E$3,2)+1-7*(WEEKDAY($E$3,2)<7))-7*20)+6)+1,'Данные'!$B:$B,C$19) | D25: =SUMIFS('Данные'!$F:$F,'Данные'!$A:$A,">="&(($E$3-WEEKDAY($E$3,2)+1-7*(WEEKDAY($E$3,2)<7))-7*20),'Данные'!$A:$A,"<"&((($E$3-WEEKDAY($E$3,2)+1-7*(WEEKDAY($E$3,2)<7))-7*20)+6)+1,'Данные'!$B:$B,D$19) | E25: =SUM(B25:D25) | F25: =IFERROR(E25/E24-1,"")
A26: =TEXT((($E$3-WEEKDAY($E$3,2)+1-7*(WEEKDAY($E$3,2)<7))-7*19),"DD.MM")&"–"&TEXT((($E$3-WEEKDAY($E$3,2)+1-7*(WEEKDAY($E$3,2)<7))-7*19)+6,"DD.MM.YYYY") | B26: =SUMIFS('Данные'!$F:$F,'Данные'!$A:$A,">="&(($E$3-WEEKDAY($E$3,2)+1-7*(WEEKDAY($E$3,2)<7))-7*19),'Данные'!$A:$A,"<"&((($E$3-WEEKDAY($E$3,2)+1-7*(WEEKDAY($E$3,2)<7))-7*19)+6)+1,'Данные'!$B:$B,B$19) | C26: =SUMIFS('Данные'!$F:$F,'Данные'!$A:$A,">="&(($E$3-WEEKDAY($E$3,2)+1-7*(WEEKDAY($E$3,2)<7))-7*19),'Данные'!$A:$A,"<"&((($E$3-WEEKDAY($E$3,2)+1-7*(WEEKDAY($E$3,2)<7))-7*19)+6)+1,'Данные'!$B:$B,C$19) | D26: =SUMIFS('Данные'!$F:$F,'Данные'!$A:$A,">="&(($E$3-WEEKDAY($E$3,2)+1-7*(WEEKDAY($E$3,2)<7))-7*19),'Данные'!$A:$A,"<"&((($E$3-WEEKDAY($E$3,2)+1-7*(WEEKDAY($E$3,2)<7))-7*19)+6)+1,'Данные'!$B:$B,D$19) | E26: =SUM(B26:D26) | F26: =IFERROR(E26/E25-1,"")
A27: =TEXT((($E$3-WEEKDAY($E$3,2)+1-7*(WEEKDAY($E$3,2)<7))-7*18),"DD.MM")&"–"&TEXT((($E$3-WEEKDAY($E$3,2)+1-7*(WEEKDAY($E$3,2)<7))-7*18)+6,"DD.MM.YYYY") | B27: =SUMIFS('Данные'!$F:$F,'Данные'!$A:$A,">="&(($E$3-WEEKDAY($E$3,2)+1-7*(WEEKDAY($E$3,2)<7))-7*18),'Данные'!$A:$A,"<"&((($E$3-WEEKDAY($E$3,2)+1-7*(WEEKDAY($E$3,2)<7))-7*18)+6)+1,'Данные'!$B:$B,B$19) | C27: =SUMIFS('Данные'!$F:$F,'Данные'!$A:$A,">="&(($E$3-WEEKDAY($E$3,2)+1-7*(WEEKDAY($E$3,2)<7))-7*18),'Данные'!$A:$A,"<"&((($E$3-WEEKDAY($E$3,2)+1-7*(WEEKDAY($E$3,2)<7))-7*18)+6)+1,'Данные'!$B:$B,C$19) | D27: =SUMIFS('Данные'!$F:$F,'Данные'!$A:$A,">="&(($E$3-WEEKDAY($E$3,2)+1-7*(WEEKDAY($E$3,2)<7))-7*18),'Данные'!$A:$A,"<"&((($E$3-WEEKDAY($E$3,2)+1-7*(WEEKDAY($E$3,2)<7))-7*18)+6)+1,'Данные'!$B:$B,D$19) | E27: =SUM(B27:D27) | F27: =IFERROR(E27/E26-1,"")
A28: =TEXT((($E$3-WEEKDAY($E$3,2)+1-7*(WEEKDAY($E$3,2)<7))-7*17),"DD.MM")&"–"&TEXT((($E$3-WEEKDAY($E$3,2)+1-7*(WEEKDAY($E$3,2)<7))-7*17)+6,"DD.MM.YYYY") | B28: =SUMIFS('Данные'!$F:$F,'Данные'!$A:$A,">="&(($E$3-WEEKDAY($E$3,2)+1-7*(WEEKDAY($E$3,2)<7))-7*17),'Данные'!$A:$A,"<"&((($E$3-WEEKDAY($E$3,2)+1-7*(WEEKDAY($E$3,2)<7))-7*17)+6)+1,'Данные'!$B:$B,B$19) | C28: =SUMIFS('Данные'!$F:$F,'Данные'!$A:$A,">="&(($E$3-WEEKDAY($E$3,2)+1-7*(WEEKDAY($E$3,2)<7))-7*17),'Данные'!$A:$A,"<"&((($E$3-WEEKDAY($E$3,2)+1-7*(WEEKDAY($E$3,2)<7))-7*17)+6)+1,'Данные'!$B:$B,C$19) | D28: =SUMIFS('Данные'!$F:$F,'Данные'!$A:$A,">="&(($E$3-WEEKDAY($E$3,2)+1-7*(WEEKDAY($E$3,2)<7))-7*17),'Данные'!$A:$A,"<"&((($E$3-WEEKDAY($E$3,2)+1-7*(WEEKDAY($E$3,2)<7))-7*17)+6)+1,'Данные'!$B:$B,D$19) | E28: =SUM(B28:D28) | F28: =IFERROR(E28/E27-1,"")
A29: =TEXT((($E$3-WEEKDAY($E$3,2)+1-7*(WEEKDAY($E$3,2)<7))-7*16),"DD.MM")&"–"&TEXT((($E$3-WEEKDAY($E$3,2)+1-7*(WEEKDAY($E$3,2)<7))-7*16)+6,"DD.MM.YYYY") | B29: =SUMIFS('Данные'!$F:$F,'Данные'!$A:$A,">="&(($E$3-WEEKDAY($E$3,2)+1-7*(WEEKDAY($E$3,2)<7))-7*16),'Данные'!$A:$A,"<"&((($E$3-WEEKDAY($E$3,2)+1-7*(WEEKDAY($E$3,2)<7))-7*16)+6)+1,'Данные'!$B:$B,B$19) | C29: =SUMIFS('Данные'!$F:$F,'Данные'!$A:$A,">="&(($E$3-WEEKDAY($E$3,2)+1-7*(WEEKDAY($E$3,2)<7))-7*16),'Данные'!$A:$A,"<"&((($E$3-WEEKDAY($E$3,2)+1-7*(WEEKDAY($E$3,2)<7))-7*16)+6)+1,'Данные'!$B:$B,C$19) | D29: =SUMIFS('Данные'!$F:$F,'Данные'!$A:$A,">="&(($E$3-WEEKDAY($E$3,2)+1-7*(WEEKDAY($E$3,2)<7))-7*16),'Данные'!$A:$A,"<"&((($E$3-WEEKDAY($E$3,2)+1-7*(WEEKDAY($E$3,2)<7))-7*16)+6)+1,'Данные'!$B:$B,D$19) | E29: =SUM(B29:D29) | F29: =IFERROR(E29/E28-1,"")
A30: =TEXT((($E$3-WEEKDAY($E$3,2)+1-7*(WEEKDAY($E$3,2)<7))-7*15),"DD.MM")&"–"&TEXT((($E$3-WEEKDAY($E$3,2)+1-7*(WEEKDAY($E$3,2)<7))-7*15)+6,"DD.MM.YYYY") | B30: =SUMIFS('Данные'!$F:$F,'Данные'!$A:$A,">="&(($E$3-WEEKDAY($E$3,2)+1-7*(WEEKDAY($E$3,2)<7))-7*15),'Данные'!$A:$A,"<"&((($E$3-WEEKDAY($E$3,2)+1-7*(WEEKDAY($E$3,2)<7))-7*15)+6)+1,'Данные'!$B:$B,B$19) | C30: =SUMIFS('Данные'!$F:$F,'Данные'!$A:$A,">="&(($E$3-WEEKDAY($E$3,2)+1-7*(WEEKDAY($E$3,2)<7))-7*15),'Данные'!$A:$A,"<"&((($E$3-WEEKDAY($E$3,2)+1-7*(WEEKDAY($E$3,2)<7))-7*15)+6)+1,'Данные'!$B:$B,C$19) | D30: =SUMIFS('Данные'!$F:$F,'Данные'!$A:$A,">="&(($E$3-WEEKDAY($E$3,2)+1-7*(WEEKDAY($E$3,2)<7))-7*15),'Данные'!$A:$A,"<"&((($E$3-WEEKDAY($E$3,2)+1-7*(WEEKDAY($E$3,2)<7))-7*15)+6)+1,'Данные'!$B:$B,D$19) | E30: =SUM(B30:D30) | F30: =IFERROR(E30/E29-1,"")
A31: =TEXT((($E$3-WEEKDAY($E$3,2)+1-7*(WEEKDAY($E$3,2)<7))-7*14),"DD.MM")&"–"&TEXT((($E$3-WEEKDAY($E$3,2)+1-7*(WEEKDAY($E$3,2)<7))-7*14)+6,"DD.MM.YYYY") | B31: =SUMIFS('Данные'!$F:$F,'Данные'!$A:$A,">="&(($E$3-WEEKDAY($E$3,2)+1-7*(WEEKDAY($E$3,2)<7))-7*14),'Данные'!$A:$A,"<"&((($E$3-WEEKDAY($E$3,2)+1-7*(WEEKDAY($E$3,2)<7))-7*14)+6)+1,'Данные'!$B:$B,B$19) | C31: =SUMIFS('Данные'!$F:$F,'Данные'!$A:$A,">="&(($E$3-WEEKDAY($E$3,2)+1-7*(WEEKDAY($E$3,2)<7))-7*14),'Данные'!$A:$A,"<"&((($E$3-WEEKDAY($E$3,2)+1-7*(WEEKDAY($E$3,2)<7))-7*14)+6)+1,'Данные'!$B:$B,C$19) | D31: =SUMIFS('Данные'!$F:$F,'Данные'!$A:$A,">="&(($E$3-WEEKDAY($E$3,2)+1-7*(WEEKDAY($E$3,2)<7))-7*14),'Данные'!$A:$A,"<"&((($E$3-WEEKDAY($E$3,2)+1-7*(WEEKDAY($E$3,2)<7))-7*14)+6)+1,'Данные'!$B:$B,D$19) | E31: =SUM(B31:D31) | F31: =IFERROR(E31/E30-1,"")
A32: =TEXT((($E$3-WEEKDAY($E$3,2)+1-7*(WEEKDAY($E$3,2)<7))-7*13),"DD.MM")&"–"&TEXT((($E$3-WEEKDAY($E$3,2)+1-7*(WEEKDAY($E$3,2)<7))-7*13)+6,"DD.MM.YYYY") | B32: =SUMIFS('Данные'!$F:$F,'Данные'!$A:$A,">="&(($E$3-WEEKDAY($E$3,2)+1-7*(WEEKDAY($E$3,2)<7))-7*13),'Данные'!$A:$A,"<"&((($E$3-WEEKDAY($E$3,2)+1-7*(WEEKDAY($E$3,2)<7))-7*13)+6)+1,'Данные'!$B:$B,B$19) | C32: =SUMIFS('Данные'!$F:$F,'Данные'!$A:$A,">="&(($E$3-WEEKDAY($E$3,2)+1-7*(WEEKDAY($E$3,2)<7))-7*13),'Данные'!$A:$A,"<"&((($E$3-WEEKDAY($E$3,2)+1-7*(WEEKDAY($E$3,2)<7))-7*13)+6)+1,'Данные'!$B:$B,C$19) | D32: =SUMIFS('Данные'!$F:$F,'Данные'!$A:$A,">="&(($E$3-WEEKDAY($E$3,2)+1-7*(WEEKDAY($E$3,2)<7))-7*13),'Данные'!$A:$A,"<"&((($E$3-WEEKDAY($E$3,2)+1-7*(WEEKDAY($E$3,2)<7))-7*13)+6)+1,'Данные'!$B:$B,D$19) | E32: =SUM(B32:D32) | F32: =IFERROR(E32/E31-1,"")
A33: =TEXT((($E$3-WEEKDAY($E$3,2)+1-7*(WEEKDAY($E$3,2)<7))-7*12),"DD.MM")&"–"&TEXT((($E$3-WEEKDAY($E$3,2)+1-7*(WEEKDAY($E$3,2)<7))-7*12)+6,"DD.MM.YYYY") | B33: =SUMIFS('Данные'!$F:$F,'Данные'!$A:$A,">="&(($E$3-WEEKDAY($E$3,2)+1-7*(WEEKDAY($E$3,2)<7))-7*12),'Данные'!$A:$A,"<"&((($E$3-WEEKDAY($E$3,2)+1-7*(WEEKDAY($E$3,2)<7))-7*12)+6)+1,'Данные'!$B:$B,B$19) | C33: =SUMIFS('Данные'!$F:$F,'Данные'!$A:$A,">="&(($E$3-WEEKDAY($E$3,2)+1-7*(WEEKDAY($E$3,2)<7))-7*12),'Данные'!$A:$A,"<"&((($E$3-WEEKDAY($E$3,2)+1-7*(WEEKDAY($E$3,2)<7))-7*12)+6)+1,'Данные'!$B:$B,C$19) | D33: =SUMIFS('Данные'!$F:$F,'Данные'!$A:$A,">="&(($E$3-WEEKDAY($E$3,2)+1-7*(WEEKDAY($E$3,2)<7))-7*12),'Данные'!$A:$A,"<"&((($E$3-WEEKDAY($E$3,2)+1-7*(WEEKDAY($E$3,2)<7))-7*12)+6)+1,'Данные'!$B:$B,D$19) | E33: =SUM(B33:D33) | F33: =IFERROR(E33/E32-1,"")
A34: =TEXT((($E$3-WEEKDAY($E$3,2)+1-7*(WEEKDAY($E$3,2)<7))-7*11),"DD.MM")&"–"&TEXT((($E$3-WEEKDAY($E$3,2)+1-7*(WEEKDAY($E$3,2)<7))-7*11)+6,"DD.MM.YYYY") | B34: =SUMIFS('Данные'!$F:$F,'Данные'!$A:$A,">="&(($E$3-WEEKDAY($E$3,2)+1-7*(WEEKDAY($E$3,2)<7))-7*11),'Данные'!$A:$A,"<"&((($E$3-WEEKDAY($E$3,2)+1-7*(WEEKDAY($E$3,2)<7))-7*11)+6)+1,'Данные'!$B:$B,B$19) | C34: =SUMIFS('Данные'!$F:$F,'Данные'!$A:$A,">="&(($E$3-WEEKDAY($E$3,2)+1-7*(WEEKDAY($E$3,2)<7))-7*11),'Данные'!$A:$A,"<"&((($E$3-WEEKDAY($E$3,2)+1-7*(WEEKDAY($E$3,2)<7))-7*11)+6)+1,'Данные'!$B:$B,C$19) | D34: =SUMIFS('Данные'!$F:$F,'Данные'!$A:$A,">="&(($E$3-WEEKDAY($E$3,2)+1-7*(WEEKDAY($E$3,2)<7))-7*11),'Данные'!$A:$A,"<"&((($E$3-WEEKDAY($E$3,2)+1-7*(WEEKDAY($E$3,2)<7))-7*11)+6)+1,'Данные'!$B:$B,D$19) | E34: =SUM(B34:D34) | F34: =IFERROR(E34/E33-1,"")
A35: =TEXT((($E$3-WEEKDAY($E$3,2)+1-7*(WEEKDAY($E$3,2)<7))-7*10),"DD.MM")&"–"&TEXT((($E$3-WEEKDAY($E$3,2)+1-7*(WEEKDAY($E$3,2)<7))-7*10)+6,"DD.MM.YYYY") | B35: =SUMIFS('Данные'!$F:$F,'Данные'!$A:$A,">="&(($E$3-WEEKDAY($E$3,2)+1-7*(WEEKDAY($E$3,2)<7))-7*10),'Данные'!$A:$A,"<"&((($E$3-WEEKDAY($E$3,2)+1-7*(WEEKDAY($E$3,2)<7))-7*10)+6)+1,'Данные'!$B:$B,B$19) | C35: =SUMIFS('Данные'!$F:$F,'Данные'!$A:$A,">="&(($E$3-WEEKDAY($E$3,2)+1-7*(WEEKDAY($E$3,2)<7))-7*10),'Данные'!$A:$A,"<"&((($E$3-WEEKDAY($E$3,2)+1-7*(WEEKDAY($E$3,2)<7))-7*10)+6)+1,'Данные'!$B:$B,C$19) | D35: =SUMIFS('Данные'!$F:$F,'Данные'!$A:$A,">="&(($E$3-WEEKDAY($E$3,2)+1-7*(WEEKDAY($E$3,2)<7))-7*10),'Данные'!$A:$A,"<"&((($E$3-WEEKDAY($E$3,2)+1-7*(WEEKDAY($E$3,2)<7))-7*10)+6)+1,'Данные'!$B:$B,D$19) | E35: =SUM(B35:D35) | F35: =IFERROR(E35/E34-1,"")
A36: =TEXT((($E$3-WEEKDAY($E$3,2)+1-7*(WEEKDAY($E$3,2)<7))-7*9),"DD.MM")&"–"&TEXT((($E$3-WEEKDAY($E$3,2)+1-7*(WEEKDAY($E$3,2)<7))-7*9)+6,"DD.MM.YYYY") | B36: =SUMIFS('Данные'!$F:$F,'Данные'!$A:$A,">="&(($E$3-WEEKDAY($E$3,2)+1-7*(WEEKDAY($E$3,2)<7))-7*9),'Данные'!$A:$A,"<"&((($E$3-WEEKDAY($E$3,2)+1-7*(WEEKDAY($E$3,2)<7))-7*9)+6)+1,'Данные'!$B:$B,B$19) | C36: =SUMIFS('Данные'!$F:$F,'Данные'!$A:$A,">="&(($E$3-WEEKDAY($E$3,2)+1-7*(WEEKDAY($E$3,2)<7))-7*9),'Данные'!$A:$A,"<"&((($E$3-WEEKDAY($E$3,2)+1-7*(WEEKDAY($E$3,2)<7))-7*9)+6)+1,'Данные'!$B:$B,C$19) | D36: =SUMIFS('Данные'!$F:$F,'Данные'!$A:$A,">="&(($E$3-WEEKDAY($E$3,2)+1-7*(WEEKDAY($E$3,2)<7))-7*9),'Данные'!$A:$A,"<"&((($E$3-WEEKDAY($E$3,2)+1-7*(WEEKDAY($E$3,2)<7))-7*9)+6)+1,'Данные'!$B:$B,D$19) | E36: =SUM(B36:D36) | F36: =IFERROR(E36/E35-1,"")
A37: =TEXT((($E$3-WEEKDAY($E$3,2)+1-7*(WEEKDAY($E$3,2)<7))-7*8),"DD.MM")&"–"&TEXT((($E$3-WEEKDAY($E$3,2)+1-7*(WEEKDAY($E$3,2)<7))-7*8)+6,"DD.MM.YYYY") | B37: =SUMIFS('Данные'!$F:$F,'Данные'!$A:$A,">="&(($E$3-WEEKDAY($E$3,2)+1-7*(WEEKDAY($E$3,2)<7))-7*8),'Данные'!$A:$A,"<"&((($E$3-WEEKDAY($E$3,2)+1-7*(WEEKDAY($E$3,2)<7))-7*8)+6)+1,'Данные'!$B:$B,B$19) | C37: =SUMIFS('Данные'!$F:$F,'Данные'!$A:$A,">="&(($E$3-WEEKDAY($E$3,2)+1-7*(WEEKDAY($E$3,2)<7))-7*8),'Данные'!$A:$A,"<"&((($E$3-WEEKDAY($E$3,2)+1-7*(WEEKDAY($E$3,2)<7))-7*8)+6)+1,'Данные'!$B:$B,C$19) | D37: =SUMIFS('Данные'!$F:$F,'Данные'!$A:$A,">="&(($E$3-WEEKDAY($E$3,2)+1-7*(WEEKDAY($E$3,2)<7))-7*8),'Данные'!$A:$A,"<"&((($E$3-WEEKDAY($E$3,2)+1-7*(WEEKDAY($E$3,2)<7))-7*8)+6)+1,'Данные'!$B:$B,D$19) | E37: =SUM(B37:D37) | F37: =IFERROR(E37/E36-1,"")
A38: =TEXT((($E$3-WEEKDAY($E$3,2)+1-7*(WEEKDAY($E$3,2)<7))-7*7),"DD.MM")&"–"&TEXT((($E$3-WEEKDAY($E$3,2)+1-7*(WEEKDAY($E$3,2)<7))-7*7)+6,"DD.MM.YYYY") | B38: =SUMIFS('Данные'!$F:$F,'Данные'!$A:$A,">="&(($E$3-WEEKDAY($E$3,2)+1-7*(WEEKDAY($E$3,2)<7))-7*7),'Данные'!$A:$A,"<"&((($E$3-WEEKDAY($E$3,2)+1-7*(WEEKDAY($E$3,2)<7))-7*7)+6)+1,'Данные'!$B:$B,B$19) | C38: =SUMIFS('Данные'!$F:$F,'Данные'!$A:$A,">="&(($E$3-WEEKDAY($E$3,2)+1-7*(WEEKDAY($E$3,2)<7))-7*7),'Данные'!$A:$A,"<"&((($E$3-WEEKDAY($E$3,2)+1-7*(WEEKDAY($E$3,2)<7))-7*7)+6)+1,'Данные'!$B:$B,C$19) | D38: =SUMIFS('Данные'!$F:$F,'Данные'!$A:$A,">="&(($E$3-WEEKDAY($E$3,2)+1-7*(WEEKDAY($E$3,2)<7))-7*7),'Данные'!$A:$A,"<"&((($E$3-WEEKDAY($E$3,2)+1-7*(WEEKDAY($E$3,2)<7))-7*7)+6)+1,'Данные'!$B:$B,D$19) | E38: =SUM(B38:D38) | F38: =IFERROR(E38/E37-1,"")
A39: =TEXT((($E$3-WEEKDAY($E$3,2)+1-7*(WEEKDAY($E$3,2)<7))-7*6),"DD.MM")&"–"&TEXT((($E$3-WEEKDAY($E$3,2)+1-7*(WEEKDAY($E$3,2)<7))-7*6)+6,"DD.MM.YYYY") | B39: =SUMIFS('Данные'!$F:$F,'Данные'!$A:$A,">="&(($E$3-WEEKDAY($E$3,2)+1-7*(WEEKDAY($E$3,2)<7))-7*6),'Данные'!$A:$A,"<"&((($E$3-WEEKDAY($E$3,2)+1-7*(WEEKDAY($E$3,2)<7))-7*6)+6)+1,'Данные'!$B:$B,B$19) | C39: =SUMIFS('Данные'!$F:$F,'Данные'!$A:$A,">="&(($E$3-WEEKDAY($E$3,2)+1-7*(WEEKDAY($E$3,2)<7))-7*6),'Данные'!$A:$A,"<"&((($E$3-WEEKDAY($E$3,2)+1-7*(WEEKDAY($E$3,2)<7))-7*6)+6)+1,'Данные'!$B:$B,C$19) | D39: =SUMIFS('Данные'!$F:$F,'Данные'!$A:$A,">="&(($E$3-WEEKDAY($E$3,2)+1-7*(WEEKDAY($E$3,2)<7))-7*6),'Данные'!$A:$A,"<"&((($E$3-WEEKDAY($E$3,2)+1-7*(WEEKDAY($E$3,2)<7))-7*6)+6)+1,'Данные'!$B:$B,D$19) | E39: =SUM(B39:D39) | F39: =IFERROR(E39/E38-1,"")
A40: =TEXT((($E$3-WEEKDAY($E$3,2)+1-7*(WEEKDAY($E$3,2)<7))-7*5),"DD.MM")&"–"&TEXT((($E$3-WEEKDAY($E$3,2)+1-7*(WEEKDAY($E$3,2)<7))-7*5)+6,"DD.MM.YYYY") | B40: =SUMIFS('Данные'!$F:$F,'Данные'!$A:$A,">="&(($E$3-WEEKDAY($E$3,2)+1-7*(WEEKDAY($E$3,2)<7))-7*5),'Данные'!$A:$A,"<"&((($E$3-WEEKDAY($E$3,2)+1-7*(WEEKDAY($E$3,2)<7))-7*5)+6)+1,'Данные'!$B:$B,B$19) | C40: =SUMIFS('Данные'!$F:$F,'Данные'!$A:$A,">="&(($E$3-WEEKDAY($E$3,2)+1-7*(WEEKDAY($E$3,2)<7))-7*5),'Данные'!$A:$A,"<"&((($E$3-WEEKDAY($E$3,2)+1-7*(WEEKDAY($E$3,2)<7))-7*5)+6)+1,'Данные'!$B:$B,C$19) | D40: =SUMIFS('Данные'!$F:$F,'Данные'!$A:$A,">="&(($E$3-WEEKDAY($E$3,2)+1-7*(WEEKDAY($E$3,2)<7))-7*5),'Данные'!$A:$A,"<"&((($E$3-WEEKDAY($E$3,2)+1-7*(WEEKDAY($E$3,2)<7))-7*5)+6)+1,'Данные'!$B:$B,D$19) | E40: =SUM(B40:D40) | F40: =IFERROR(E40/E39-1,"")
A41: =TEXT((($E$3-WEEKDAY($E$3,2)+1-7*(WEEKDAY($E$3,2)<7))-7*4),"DD.MM")&"–"&TEXT((($E$3-WEEKDAY($E$3,2)+1-7*(WEEKDAY($E$3,2)<7))-7*4)+6,"DD.MM.YYYY") | B41: =SUMIFS('Данные'!$F:$F,'Данные'!$A:$A,">="&(($E$3-WEEKDAY($E$3,2)+1-7*(WEEKDAY($E$3,2)<7))-7*4),'Данные'!$A:$A,"<"&((($E$3-WEEKDAY($E$3,2)+1-7*(WEEKDAY($E$3,2)<7))-7*4)+6)+1,'Данные'!$B:$B,B$19) | C41: =SUMIFS('Данные'!$F:$F,'Данные'!$A:$A,">="&(($E$3-WEEKDAY($E$3,2)+1-7*(WEEKDAY($E$3,2)<7))-7*4),'Данные'!$A:$A,"<"&((($E$3-WEEKDAY($E$3,2)+1-7*(WEEKDAY($E$3,2)<7))-7*4)+6)+1,'Данные'!$B:$B,C$19) | D41: =SUMIFS('Данные'!$F:$F,'Данные'!$A:$A,">="&(($E$3-WEEKDAY($E$3,2)+1-7*(WEEKDAY($E$3,2)<7))-7*4),'Данные'!$A:$A,"<"&((($E$3-WEEKDAY($E$3,2)+1-7*(WEEKDAY($E$3,2)<7))-7*4)+6)+1,'Данные'!$B:$B,D$19) | E41: =SUM(B41:D41) | F41: =IFERROR(E41/E40-1,"")
A42: =TEXT((($E$3-WEEKDAY($E$3,2)+1-7*(WEEKDAY($E$3,2)<7))-7*3),"DD.MM")&"–"&TEXT((($E$3-WEEKDAY($E$3,2)+1-7*(WEEKDAY($E$3,2)<7))-7*3)+6,"DD.MM.YYYY") | B42: =SUMIFS('Данные'!$F:$F,'Данные'!$A:$A,">="&(($E$3-WEEKDAY($E$3,2)+1-7*(WEEKDAY($E$3,2)<7))-7*3),'Данные'!$A:$A,"<"&((($E$3-WEEKDAY($E$3,2)+1-7*(WEEKDAY($E$3,2)<7))-7*3)+6)+1,'Данные'!$B:$B,B$19) | C42: =SUMIFS('Данные'!$F:$F,'Данные'!$A:$A,">="&(($E$3-WEEKDAY($E$3,2)+1-7*(WEEKDAY($E$3,2)<7))-7*3),'Данные'!$A:$A,"<"&((($E$3-WEEKDAY($E$3,2)+1-7*(WEEKDAY($E$3,2)<7))-7*3)+6)+1,'Данные'!$B:$B,C$19) | D42: =SUMIFS('Данные'!$F:$F,'Данные'!$A:$A,">="&(($E$3-WEEKDAY($E$3,2)+1-7*(WEEKDAY($E$3,2)<7))-7*3),'Данные'!$A:$A,"<"&((($E$3-WEEKDAY($E$3,2)+1-7*(WEEKDAY($E$3,2)<7))-7*3)+6)+1,'Данные'!$B:$B,D$19) | E42: =SUM(B42:D42) | F42: =IFERROR(E42/E41-1,"")
...

Sheet Направление 1
A1: ="Сова · "&$B$3
A2: ="Итоги всех кампаний кабинета VK Реклама · данные по "&TEXT($E$3,"DD.MM.YYYY")
A3: Направление | B3: ='⚙ Настройки'!$A$2 | D3: Данные по | E3: ='⚙ Настройки'!$B$7 | G3: Период с | I3: по | N3: 📈 Подписки и расход по дням за период выше
H4: =IF(AND(ISNUMBER(H3),ISNUMBER(J3),H3>J3),"⚠ Дата «с» позже даты «по»",IF(OR(ISNUMBER(H3),ISNUMBER(J3)),"Сравнение — с предыдущим периодом той же длины. Очистите поля, чтобы вернуть текущий месяц.","Пусто — текущий месяц. Дату выбирают двойным щелчком."))
A5: =IF(OR(ISNUMBER($H$3),ISNUMBER($J$3)),"Выбранный период против предыдущего той же длины","Этот месяц против тех же дней прошлого")
A6: Период | B6: Расход | C6: Расход с НДС | D6: Показы | E6: Клики | F6: CTR | G6: CPC | H6: Подписки | I6: Цена подписки | J6: CR в подписку | K6: с | L6: по
A7: =IF(OR(ISNUMBER($H$3),ISNUMBER($J$3)),"Выбранный период","Этот месяц") | B7: =SUMIFS('Данные'!$C:$C,'Данные'!$A:$A,">="&$K$7,'Данные'!$A:$A,"<"&$L$7+1,'Данные'!$B:$B,$B$3) | C7: =B7*(100+22)/100 | D7: =SUMIFS('Данные'!$D:$D,'Данные'!$A:$A,">="&$K$7,'Данные'!$A:$A,"<"&$L$7+1,'Данные'!$B:$B,$B$3) | E7: =SUMIFS('Данные'!$E:$E,'Данные'!$A:$A,">="&$K$7,'Данные'!$A:$A,"<"&$L$7+1,'Данные'!$B:$B,$B$3) | F7: =IFERROR(E7/D7,"") | G7: =IFERROR(B7/E7,"") | H7: =SUMIFS('Данные'!$F:$F,'Данные'!$A:$A,">="&$K$7,'Данные'!$A:$A,"<"&$L$7+1,'Данные'!$B:$B,$B$3) | I7: =IFERROR(B7/H7,"") | J7: =IFERROR(H7/E7,"") | K7: =IF(ISNUMBER($H$3),$H$3,DATE(YEAR(L7),MONTH(L7),1)) | L7: =IF(ISNUMBER($J$3),$J$3,$E$3)
A8: =IF(OR(ISNUMBER($H$3),ISNUMBER($J$3)),"Предыдущий, той же длины","Прошлый, те же дни") | B8: =SUMIFS('Данные'!$C:$C,'Данные'!$A:$A,">="&$K$8,'Данные'!$A:$A,"<"&$L$8+1,'Данные'!$B:$B,$B$3) | C8: =B8*(100+22)/100 | D8: =SUMIFS('Данные'!$D:$D,'Данные'!$A:$A,">="&$K$8,'Данные'!$A:$A,"<"&$L$8+1,'Данные'!$B:$B,$B$3) | E8: =SUMIFS('Данные'!$E:$E,'Данные'!$A:$A,">="&$K$8,'Данные'!$A:$A,"<"&$L$8+1,'Данные'!$B:$B,$B$3) | F8: =IFERROR(E8/D8,"") | G8: =IFERROR(B8/E8,"") | H8: =SUMIFS('Данные'!$F:$F,'Данные'!$A:$A,">="&$K$8,'Данные'!$A:$A,"<"&$L$8+1,'Данные'!$B:$B,$B$3) | I8: =IFERROR(B8/H8,"") | J8: =IFERROR(H8/E8,"") | K8: =IF(OR(ISNUMBER($H$3),ISNUMBER($J$3)),2*K7-L7-1,EDATE(K7,-1)) | L8: =IF(OR(ISNUMBER($H$3),ISNUMBER($J$3)),K7-1,EDATE(L7,-1))
A9: Изменение | B9: =IFERROR(B7/B8-1,"") | C9: =IFERROR(C7/C8-1,"") | D9: =IFERROR(D7/D8-1,"") | E9: =IFERROR(E7/E8-1,"") | F9: =IFERROR(F7/F8-1,"") | G9: =IFERROR(G7/G8-1,"") | H9: =IFERROR(H7/H8-1,"") | I9: =IFERROR(I7/I8-1,"") | J9: =IFERROR(J7/J8-1,"")
A11: 🗓 По завершённым неделям (26)
A12: Неделя | B12: Расход | C12: Расход с НДС | D12: Показы | E12: Клики | F12: CTR | G12: CPC | H12: Подписки | I12: Цена подписки | J12: CR в подписку
A13: =TEXT((($E$3-WEEKDAY($E$3,2)+1-7*(WEEKDAY($E$3,2)<7))-7*25),"DD.MM")&"–"&TEXT((($E$3-WEEKDAY($E$3,2)+1-7*(WEEKDAY($E$3,2)<7))-7*25)+6,"DD.MM.YYYY") | B13: =SUMIFS('Данные'!$C:$C,'Данные'!$A:$A,">="&(($E$3-WEEKDAY($E$3,2)+1-7*(WEEKDAY($E$3,2)<7))-7*25),'Данные'!$A:$A,"<"&((($E$3-WEEKDAY($E$3,2)+1-7*(WEEKDAY($E$3,2)<7))-7*25)+6)+1,'Данные'!$B:$B,$B$3) | C13: =B13*(100+22)/100 | D13: =SUMIFS('Данные'!$D:$D,'Данные'!$A:$A,">="&(($E$3-WEEKDAY($E$3,2)+1-7*(WEEKDAY($E$3,2)<7))-7*25),'Данные'!$A:$A,"<"&((($E$3-WEEKDAY($E$3,2)+1-7*(WEEKDAY($E$3,2)<7))-7*25)+6)+1,'Данные'!$B:$B,$B$3) | E13: =SUMIFS('Данные'!$E:$E,'Данные'!$A:$A,">="&(($E$3-WEEKDAY($E$3,2)+1-7*(WEEKDAY($E$3,2)<7))-7*25),'Данные'!$A:$A,"<"&((($E$3-WEEKDAY($E$3,2)+1-7*(WEEKDAY($E$3,2)<7))-7*25)+6)+1,'Данные'!$B:$B,$B$3) | F13: =IFERROR(E13/D13,"") | G13: =IFERROR(B13/E13,"") | H13: =SUMIFS('Данные'!$F:$F,'Данные'!$A:$A,">="&(($E$3-WEEKDAY($E$3,2)+1-7*(WEEKDAY($E$3,2)<7))-7*25),'Данные'!$A:$A,"<"&((($E$3-WEEKDAY($E$3,2)+1-7*(WEEKDAY($E$3,2)<7))-7*25)+6)+1,'Данные'!$B:$B,$B$3) | I13: =IFERROR(B13/H13,"") | J13: =IFERROR(H13/E13,"")
A14: =TEXT((($E$3-WEEKDAY($E$3,2)+1-7*(WEEKDAY($E$3,2)<7))-7*24),"DD.MM")&"–"&TEXT((($E$3-WEEKDAY($E$3,2)+1-7*(WEEKDAY($E$3,2)<7))-7*24)+6,"DD.MM.YYYY") | B14: =SUMIFS('Данные'!$C:$C,'Данные'!$A:$A,">="&(($E$3-WEEKDAY($E$3,2)+1-7*(WEEKDAY($E$3,2)<7))-7*24),'Данные'!$A:$A,"<"&((($E$3-WEEKDAY($E$3,2)+1-7*(WEEKDAY($E$3,2)<7))-7*24)+6)+1,'Данные'!$B:$B,$B$3) | C14: =B14*(100+22)/100 | D14: =SUMIFS('Данные'!$D:$D,'Данные'!$A:$A,">="&(($E$3-WEEKDAY($E$3,2)+1-7*(WEEKDAY($E$3,2)<7))-7*24),'Данные'!$A:$A,"<"&((($E$3-WEEKDAY($E$3,2)+1-7*(WEEKDAY($E$3,2)<7))-7*24)+6)+1,'Данные'!$B:$B,$B$3) | E14: =SUMIFS('Данные'!$E:$E,'Данные'!$A:$A,">="&(($E$3-WEEKDAY($E$3,2)+1-7*(WEEKDAY($E$3,2)<7))-7*24),'Данные'!$A:$A,"<"&((($E$3-WEEKDAY($E$3,2)+1-7*(WEEKDAY($E$3,2)<7))-7*24)+6)+1,'Данные'!$B:$B,$B$3) | F14: =IFERROR(E14/D14,"") | G14: =IFERROR(B14/E14,"") | H14: =SUMIFS('Данные'!$F:$F,'Данные'!$A:$A,">="&(($E$3-WEEKDAY($E$3,2)+1-7*(WEEKDAY($E$3,2)<7))-7*24),'Данные'!$A:$A,"<"&((($E$3-WEEKDAY($E$3,2)+1-7*(WEEKDAY($E$3,2)<7))-7*24)+6)+1,'Данные'!$B:$B,$B$3) | I14: =IFERROR(B14/H14,"") | J14: =IFERROR(H14/E14,"")
A15: =TEXT((($E$3-WEEKDAY($E$3,2)+1-7*(WEEKDAY($E$3,2)<7))-7*23),"DD.MM")&"–"&TEXT((($E$3-WEEKDAY($E$3,2)+1-7*(WEEKDAY($E$3,2)<7))-7*23)+6,"DD.MM.YYYY") | B15: =SUMIFS('Данные'!$C:$C,'Данные'!$A:$A,">="&(($E$3-WEEKDAY($E$3,2)+1-7*(WEEKDAY($E$3,2)<7))-7*23),'Данные'!$A:$A,"<"&((($E$3-WEEKDAY($E$3,2)+1-7*(WEEKDAY($E$3,2)<7))-7*23)+6)+1,'Данные'!$B:$B,$B$3) | C15: =B15*(100+22)/100 | D15: =SUMIFS('Данные'!$D:$D,'Данные'!$A:$A,">="&(($E$3-WEEKDAY($E$3,2)+1-7*(WEEKDAY($E$3,2)<7))-7*23),'Данные'!$A:$A,"<"&((($E$3-WEEKDAY($E$3,2)+1-7*(WEEKDAY($E$3,2)<7))-7*23)+6)+1,'Данные'!$B:$B,$B$3) | E15: =SUMIFS('Данные'!$E:$E,'Данные'!$A:$A,">="&(($E$3-WEEKDAY($E$3,2)+1-7*(WEEKDAY($E$3,2)<7))-7*23),'Данные'!$A:$A,"<"&((($E$3-WEEKDAY($E$3,2)+1-7*(WEEKDAY($E$3,2)<7))-7*23)+6)+1,'Данные'!$B:$B,$B$3) | F15: =IFERROR(E15/D15,"") | G15: =IFERROR(B15/E15,"") | H15: =SUMIFS('Данные'!$F:$F,'Данные'!$A:$A,">="&(($E$3-WEEKDAY($E$3,2)+1-7*(WEEKDAY($E$3,2)<7))-7*23),'Данные'!$A:$A,"<"&((($E$3-WEEKDAY($E$3,2)+1-7*(WEEKDAY($E$3,2)<7))-7*23)+6)+1,'Данные'!$B:$B,$B$3) | I15: =IFERROR(B15/H15,"") | J15: =IFERROR(H15/E15,"")
A16: =TEXT((($E$3-WEEKDAY($E$3,2)+1-7*(WEEKDAY($E$3,2)<7))-7*22),"DD.MM")&"–"&TEXT((($E$3-WEEKDAY($E$3,2)+1-7*(WEEKDAY($E$3,2)<7))-7*22)+6,"DD.MM.YYYY") | B16: =SUMIFS('Данные'!$C:$C,'Данные'!$A:$A,">="&(($E$3-WEEKDAY($E$3,2)+1-7*(WEEKDAY($E$3,2)<7))-7*22),'Данные'!$A:$A,"<"&((($E$3-WEEKDAY($E$3,2)+1-7*(WEEKDAY($E$3,2)<7))-7*22)+6)+1,'Данные'!$B:$B,$B$3) | C16: =B16*(100+22)/100 | D16: =SUMIFS('Данные'!$D:$D,'Данные'!$A:$A,">="&(($E$3-WEEKDAY($E$3,2)+1-7*(WEEKDAY($E$3,2)<7))-7*22),'Данные'!$A:$A,"<"&((($E$3-WEEKDAY($E$3,2)+1-7*(WEEKDAY($E$3,2)<7))-7*22)+6)+1,'Данные'!$B:$B,$B$3) | E16: =SUMIFS('Данные'!$E:$E,'Данные'!$A:$A,">="&(($E$3-WEEKDAY($E$3,2)+1-7*(WEEKDAY($E$3,2)<7))-7*22),'Данные'!$A:$A,"<"&((($E$3-WEEKDAY($E$3,2)+1-7*(WEEKDAY($E$3,2)<7))-7*22)+6)+1,'Данные'!$B:$B,$B$3) | F16: =IFERROR(E16/D16,"") | G16: =IFERROR(B16/E16,"") | H16: =SUMIFS('Данные'!$F:$F,'Данные'!$A:$A,">="&(($E$3-WEEKDAY($E$3,2)+1-7*(WEEKDAY($E$3,2)<7))-7*22),'Данные'!$A:$A,"<"&((($E$3-WEEKDAY($E$3,2)+1-7*(WEEKDAY($E$3,2)<7))-7*22)+6)+1,'Данные'!$B:$B,$B$3) | I16: =IFERROR(B16/H16,"") | J16: =IFERROR(H16/E16,"")
A17: =TEXT((($E$3-WEEKDAY($E$3,2)+1-7*(WEEKDAY($E$3,2)<7))-7*21),"DD.MM")&"–"&TEXT((($E$3-WEEKDAY($E$3,2)+1-7*(WEEKDAY($E$3,2)<7))-7*21)+6,"DD.MM.YYYY") | B17: =SUMIFS('Данные'!$C:$C,'Данные'!$A:$A,">="&(($E$3-WEEKDAY($E$3,2)+1-7*(WEEKDAY($E$3,2)<7))-7*21),'Данные'!$A:$A,"<"&((($E$3-WEEKDAY($E$3,2)+1-7*(WEEKDAY($E$3,2)<7))-7*21)+6)+1,'Данные'!$B:$B,$B$3) | C17: =B17*(100+22)/100 | D17: =SUMIFS('Данные'!$D:$D,'Данные'!$A:$A,">="&(($E$3-WEEKDAY($E$3,2)+1-7*(WEEKDAY($E$3,2)<7))-7*21),'Данные'!$A:$A,"<"&((($E$3-WEEKDAY($E$3,2)+1-7*(WEEKDAY($E$3,2)<7))-7*21)+6)+1,'Данные'!$B:$B,$B$3) | E17: =SUMIFS('Данные'!$E:$E,'Данные'!$A:$A,">="&(($E$3-WEEKDAY($E$3,2)+1-7*(WEEKDAY($E$3,2)<7))-7*21),'Данные'!$A:$A,"<"&((($E$3-WEEKDAY($E$3,2)+1-7*(WEEKDAY($E$3,2)<7))-7*21)+6)+1,'Данные'!$B:$B,$B$3) | F17: =IFERROR(E17/D17,"") | G17: =IFERROR(B17/E17,"") | H17: =SUMIFS('Данные'!$F:$F,'Данные'!$A:$A,">="&(($E$3-WEEKDAY($E$3,2)+1-7*(WEEKDAY($E$3,2)<7))-7*21),'Данные'!$A:$A,"<"&((($E$3-WEEKDAY($E$3,2)+1-7*(WEEKDAY($E$3,2)<7))-7*21)+6)+1,'Данные'!$B:$B,$B$3) | I17: =IFERROR(B17/H17,"") | J17: =IFERROR(H17/E17,"")
A18: =TEXT((($E$3-WEEKDAY($E$3,2)+1-7*(WEEKDAY($E$3,2)<7))-7*20),"DD.MM")&"–"&TEXT((($E$3-WEEKDAY($E$3,2)+1-7*(WEEKDAY($E$3,2)<7))-7*20)+6,"DD.MM.YYYY") | B18: =SUMIFS('Данные'!$C:$C,'Данные'!$A:$A,">="&(($E$3-WEEKDAY($E$3,2)+1-7*(WEEKDAY($E$3,2)<7))-7*20),'Данные'!$A:$A,"<"&((($E$3-WEEKDAY($E$3,2)+1-7*(WEEKDAY($E$3,2)<7))-7*20)+6)+1,'Данные'!$B:$B,$B$3) | C18: =B18*(100+22)/100 | D18: =SUMIFS('Данные'!$D:$D,'Данные'!$A:$A,">="&(($E$3-WEEKDAY($E$3,2)+1-7*(WEEKDAY($E$3,2)<7))-7*20),'Данные'!$A:$A,"<"&((($E$3-WEEKDAY($E$3,2)+1-7*(WEEKDAY($E$3,2)<7))-7*20)+6)+1,'Данные'!$B:$B,$B$3) | E18: =SUMIFS('Данные'!$E:$E,'Данные'!$A:$A,">="&(($E$3-WEEKDAY($E$3,2)+1-7*(WEEKDAY($E$3,2)<7))-7*20),'Данные'!$A:$A,"<"&((($E$3-WEEKDAY($E$3,2)+1-7*(WEEKDAY($E$3,2)<7))-7*20)+6)+1,'Данные'!$B:$B,$B$3) | F18: =IFERROR(E18/D18,"") | G18: =IFERROR(B18/E18,"") | H18: =SUMIFS('Данные'!$F:$F,'Данные'!$A:$A,">="&(($E$3-WEEKDAY($E$3,2)+1-7*(WEEKDAY($E$3,2)<7))-7*20),'Данные'!$A:$A,"<"&((($E$3-WEEKDAY($E$3,2)+1-7*(WEEKDAY($E$3,2)<7))-7*20)+6)+1,'Данные'!$B:$B,$B$3) | I18: =IFERROR(B18/H18,"") | J18: =IFERROR(H18/E18,"")
A19: =TEXT((($E$3-WEEKDAY($E$3,2)+1-7*(WEEKDAY($E$3,2)<7))-7*19),"DD.MM")&"–"&TEXT((($E$3-WEEKDAY($E$3,2)+1-7*(WEEKDAY($E$3,2)<7))-7*19)+6,"DD.MM.YYYY") | B19: =SUMIFS('Данные'!$C:$C,'Данные'!$A:$A,">="&(($E$3-WEEKDAY($E$3,2)+1-7*(WEEKDAY($E$3,2)<7))-7*19),'Данные'!$A:$A,"<"&((($E$3-WEEKDAY($E$3,2)+1-7*(WEEKDAY($E$3,2)<7))-7*19)+6)+1,'Данные'!$B:$B,$B$3) | C19: =B19*(100+22)/100 | D19: =SUMIFS('Данные'!$D:$D,'Данные'!$A:$A,">="&(($E$3-WEEKDAY($E$3,2)+1-7*(WEEKDAY($E$3,2)<7))-7*19),'Данные'!$A:$A,"<"&((($E$3-WEEKDAY($E$3,2)+1-7*(WEEKDAY($E$3,2)<7))-7*19)+6)+1,'Данные'!$B:$B,$B$3) | E19: =SUMIFS('Данные'!$E:$E,'Данные'!$A:$A,">="&(($E$3-WEEKDAY($E$3,2)+1-7*(WEEKDAY($E$3,2)<7))-7*19),'Данные'!$A:$A,"<"&((($E$3-WEEKDAY($E$3,2)+1-7*(WEEKDAY($E$3,2)<7))-7*19)+6)+1,'Данные'!$B:$B,$B$3) | F19: =IFERROR(E19/D19,"") | G19: =IFERROR(B19/E19,"") | H19: =SUMIFS('Данные'!$F:$F,'Данные'!$A:$A,">="&(($E$3-WEEKDAY($E$3,2)+1-7*(WEEKDAY($E$3,2)<7))-7*19),'Данные'!$A:$A,"<"&((($E$3-WEEKDAY($E$3,2)+1-7*(WEEKDAY($E$3,2)<7))-7*19)+6)+1,'Данные'!$B:$B,$B$3) | I19: =IFERROR(B19/H19,"") | J19: =IFERROR(H19/E19,"")
A20: =TEXT((($E$3-WEEKDAY($E$3,2)+1-7*(WEEKDAY($E$3,2)<7))-7*18),"DD.MM")&"–"&TEXT((($E$3-WEEKDAY($E$3,2)+1-7*(WEEKDAY($E$3,2)<7))-7*18)+6,"DD.MM.YYYY") | B20: =SUMIFS('Данные'!$C:$C,'Данные'!$A:$A,">="&(($E$3-WEEKDAY($E$3,2)+1-7*(WEEKDAY($E$3,2)<7))-7*18),'Данные'!$A:$A,"<"&((($E$3-WEEKDAY($E$3,2)+1-7*(WEEKDAY($E$3,2)<7))-7*18)+6)+1,'Данные'!$B:$B,$B$3) | C20: =B20*(100+22)/100 | D20: =SUMIFS('Данные'!$D:$D,'Данные'!$A:$A,">="&(($E$3-WEEKDAY($E$3,2)+1-7*(WEEKDAY($E$3,2)<7))-7*18),'Данные'!$A:$A,"<"&((($E$3-WEEKDAY($E$3,2)+1-7*(WEEKDAY($E$3,2)<7))-7*18)+6)+1,'Данные'!$B:$B,$B$3) | E20: =SUMIFS('Данные'!$E:$E,'Данные'!$A:$A,">="&(($E$3-WEEKDAY($E$3,2)+1-7*(WEEKDAY($E$3,2)<7))-7*18),'Данные'!$A:$A,"<"&((($E$3-WEEKDAY($E$3,2)+1-7*(WEEKDAY($E$3,2)<7))-7*18)+6)+1,'Данные'!$B:$B,$B$3) | F20: =IFERROR(E20/D20,"") | G20: =IFERROR(B20/E20,"") | H20: =SUMIFS('Данные'!$F:$F,'Данные'!$A:$A,">="&(($E$3-WEEKDAY($E$3,2)+1-7*(WEEKDAY($E$3,2)<7))-7*18),'Данные'!$A:$A,"<"&((($E$3-WEEKDAY($E$3,2)+1-7*(WEEKDAY($E$3,2)<7))-7*18)+6)+1,'Данные'!$B:$B,$B$3) | I20: =IFERROR(B20/H20,"") | J20: =IFERROR(H20/E20,"")
A21: =TEXT((($E$3-WEEKDAY($E$3,2)+1-7*(WEEKDAY($E$3,2)<7))-7*17),"DD.MM")&"–"&TEXT((($E$3-WEEKDAY($E$3,2)+1-7*(WEEKDAY($E$3,2)<7))-7*17)+6,"DD.MM.YYYY") | B21: =SUMIFS('Данные'!$C:$C,'Данные'!$A:$A,">="&(($E$3-WEEKDAY($E$3,2)+1-7*(WEEKDAY($E$3,2)<7))-7*17),'Данные'!$A:$A,"<"&((($E$3-WEEKDAY($E$3,2)+1-7*(WEEKDAY($E$3,2)<7))-7*17)+6)+1,'Данные'!$B:$B,$B$3) | C21: =B21*(100+22)/100 | D21: =SUMIFS('Данные'!$D:$D,'Данные'!$A:$A,">="&(($E$3-WEEKDAY($E$3,2)+1-7*(WEEKDAY($E$3,2)<7))-7*17),'Данные'!$A:$A,"<"&((($E$3-WEEKDAY($E$3,2)+1-7*(WEEKDAY($E$3,2)<7))-7*17)+6)+1,'Данные'!$B:$B,$B$3) | E21: =SUMIFS('Данные'!$E:$E,'Данные'!$A:$A,">="&(($E$3-WEEKDAY($E$3,2)+1-7*(WEEKDAY($E$3,2)<7))-7*17),'Данные'!$A:$A,"<"&((($E$3-WEEKDAY($E$3,2)+1-7*(WEEKDAY($E$3,2)<7))-7*17)+6)+1,'Данные'!$B:$B,$B$3) | F21: =IFERROR(E21/D21,"") | G21: =IFERROR(B21/E21,"") | H21: =SUMIFS('Данные'!$F:$F,'Данные'!$A:$A,">="&(($E$3-WEEKDAY($E$3,2)+1-7*(WEEKDAY($E$3,2)<7))-7*17),'Данные'!$A:$A,"<"&((($E$3-WEEKDAY($E$3,2)+1-7*(WEEKDAY($E$3,2)<7))-7*17)+6)+1,'Данные'!$B:$B,$B$3) | I21: =IFERROR(B21/H21,"") | J21: =IFERROR(H21/E21,"")
A22: =TEXT((($E$3-WEEKDAY($E$3,2)+1-7*(WEEKDAY($E$3,2)<7))-7*16),"DD.MM")&"–"&TEXT((($E$3-WEEKDAY($E$3,2)+1-7*(WEEKDAY($E$3,2)<7))-7*16)+6,"DD.MM.YYYY") | B22: =SUMIFS('Данные'!$C:$C,'Данные'!$A:$A,">="&(($E$3-WEEKDAY($E$3,2)+1-7*(WEEKDAY($E$3,2)<7))-7*16),'Данные'!$A:$A,"<"&((($E$3-WEEKDAY($E$3,2)+1-7*(WEEKDAY($E$3,2)<7))-7*16)+6)+1,'Данные'!$B:$B,$B$3) | C22: =B22*(100+22)/100 | D22: =SUMIFS('Данные'!$D:$D,'Данные'!$A:$A,">="&(($E$3-WEEKDAY($E$3,2)+1-7*(WEEKDAY($E$3,2)<7))-7*16),'Данные'!$A:$A,"<"&((($E$3-WEEKDAY($E$3,2)+1-7*(WEEKDAY($E$3,2)<7))-7*16)+6)+1,'Данные'!$B:$B,$B$3) | E22: =SUMIFS('Данные'!$E:$E,'Данные'!$A:$A,">="&(($E$3-WEEKDAY($E$3,2)+1-7*(WEEKDAY($E$3,2)<7))-7*16),'Данные'!$A:$A,"<"&((($E$3-WEEKDAY($E$3,2)+1-7*(WEEKDAY($E$3,2)<7))-7*16)+6)+1,'Данные'!$B:$B,$B$3) | F22: =IFERROR(E22/D22,"") | G22: =IFERROR(B22/E22,"") | H22: =SUMIFS('Данные'!$F:$F,'Данные'!$A:$A,">="&(($E$3-WEEKDAY($E$3,2)+1-7*(WEEKDAY($E$3,2)<7))-7*16),'Данные'!$A:$A,"<"&((($E$3-WEEKDAY($E$3,2)+1-7*(WEEKDAY($E$3,2)<7))-7*16)+6)+1,'Данные'!$B:$B,$B$3) | I22: =IFERROR(B22/H22,"") | J22: =IFERROR(H22/E22,"")
A23: =TEXT((($E$3-WEEKDAY($E$3,2)+1-7*(WEEKDAY($E$3,2)<7))-7*15),"DD.MM")&"–"&TEXT((($E$3-WEEKDAY($E$3,2)+1-7*(WEEKDAY($E$3,2)<7))-7*15)+6,"DD.MM.YYYY") | B23: =SUMIFS('Данные'!$C:$C,'Данные'!$A:$A,">="&(($E$3-WEEKDAY($E$3,2)+1-7*(WEEKDAY($E$3,2)<7))-7*15),'Данные'!$A:$A,"<"&((($E$3-WEEKDAY($E$3,2)+1-7*(WEEKDAY($E$3,2)<7))-7*15)+6)+1,'Данные'!$B:$B,$B$3) | C23: =B23*(100+22)/100 | D23: =SUMIFS('Данные'!$D:$D,'Данные'!$A:$A,">="&(($E$3-WEEKDAY($E$3,2)+1-7*(WEEKDAY($E$3,2)<7))-7*15),'Данные'!$A:$A,"<"&((($E$3-WEEKDAY($E$3,2)+1-7*(WEEKDAY($E$3,2)<7))-7*15)+6)+1,'Данные'!$B:$B,$B$3) | E23: =SUMIFS('Данные'!$E:$E,'Данные'!$A:$A,">="&(($E$3-WEEKDAY($E$3,2)+1-7*(WEEKDAY($E$3,2)<7))-7*15),'Данные'!$A:$A,"<"&((($E$3-WEEKDAY($E$3,2)+1-7*(WEEKDAY($E$3,2)<7))-7*15)+6)+1,'Данные'!$B:$B,$B$3) | F23: =IFERROR(E23/D23,"") | G23: =IFERROR(B23/E23,"") | H23: =SUMIFS('Данные'!$F:$F,'Данные'!$A:$A,">="&(($E$3-WEEKDAY($E$3,2)+1-7*(WEEKDAY($E$3,2)<7))-7*15),'Данные'!$A:$A,"<"&((($E$3-WEEKDAY($E$3,2)+1-7*(WEEKDAY($E$3,2)<7))-7*15)+6)+1,'Данные'!$B:$B,$B$3) | I23: =IFERROR(B23/H23,"") | J23: =IFERROR(H23/E23,"")
A24: =TEXT((($E$3-WEEKDAY($E$3,2)+1-7*(WEEKDAY($E$3,2)<7))-7*14),"DD.MM")&"–"&TEXT((($E$3-WEEKDAY($E$3,2)+1-7*(WEEKDAY($E$3,2)<7))-7*14)+6,"DD.MM.YYYY") | B24: =SUMIFS('Данные'!$C:$C,'Данные'!$A:$A,">="&(($E$3-WEEKDAY($E$3,2)+1-7*(WEEKDAY($E$3,2)<7))-7*14),'Данные'!$A:$A,"<"&((($E$3-WEEKDAY($E$3,2)+1-7*(WEEKDAY($E$3,2)<7))-7*14)+6)+1,'Данные'!$B:$B,$B$3) | C24: =B24*(100+22)/100 | D24: =SUMIFS('Данные'!$D:$D,'Данные'!$A:$A,">="&(($E$3-WEEKDAY($E$3,2)+1-7*(WEEKDAY($E$3,2)<7))-7*14),'Данные'!$A:$A,"<"&((($E$3-WEEKDAY($E$3,2)+1-7*(WEEKDAY($E$3,2)<7))-7*14)+6)+1,'Данные'!$B:$B,$B$3) | E24: =SUMIFS('Данные'!$E:$E,'Данные'!$A:$A,">="&(($E$3-WEEKDAY($E$3,2)+1-7*(WEEKDAY($E$3,2)<7))-7*14),'Данные'!$A:$A,"<"&((($E$3-WEEKDAY($E$3,2)+1-7*(WEEKDAY($E$3,2)<7))-7*14)+6)+1,'Данные'!$B:$B,$B$3) | F24: =IFERROR(E24/D24,"") | G24: =IFERROR(B24/E24,"") | H24: =SUMIFS('Данные'!$F:$F,'Данные'!$A:$A,">="&(($E$3-WEEKDAY($E$3,2)+1-7*(WEEKDAY($E$3,2)<7))-7*14),'Данные'!$A:$A,"<"&((($E$3-WEEKDAY($E$3,2)+1-7*(WEEKDAY($E$3,2)<7))-7*14)+6)+1,'Данные'!$B:$B,$B$3) | I24: =IFERROR(B24/H24,"") | J24: =IFERROR(H24/E24,"")
A25: =TEXT((($E$3-WEEKDAY($E$3,2)+1-7*(WEEKDAY($E$3,2)<7))-7*13),"DD.MM")&"–"&TEXT((($E$3-WEEKDAY($E$3,2)+1-7*(WEEKDAY($E$3,2)<7))-7*13)+6,"DD.MM.YYYY") | B25: =SUMIFS('Данные'!$C:$C,'Данные'!$A:$A,">="&(($E$3-WEEKDAY($E$3,2)+1-7*(WEEKDAY($E$3,2)<7))-7*13),'Данные'!$A:$A,"<"&((($E$3-WEEKDAY($E$3,2)+1-7*(WEEKDAY($E$3,2)<7))-7*13)+6)+1,'Данные'!$B:$B,$B$3) | C25: =B25*(100+22)/100 | D25: =SUMIFS('Данные'!$D:$D,'Данные'!$A:$A,">="&(($E$3-WEEKDAY($E$3,2)+1-7*(WEEKDAY($E$3,2)<7))-7*13),'Данные'!$A:$A,"<"&((($E$3-WEEKDAY($E$3,2)+1-7*(WEEKDAY($E$3,2)<7))-7*13)+6)+1,'Данные'!$B:$B,$B$3) | E25: =SUMIFS('Данные'!$E:$E,'Данные'!$A:$A,">="&(($E$3-WEEKDAY($E$3,2)+1-7*(WEEKDAY($E$3,2)<7))-7*13),'Данные'!$A:$A,"<"&((($E$3-WEEKDAY($E$3,2)+1-7*(WEEKDAY($E$3,2)<7))-7*13)+6)+1,'Данные'!$B:$B,$B$3) | F25: =IFERROR(E25/D25,"") | G25: =IFERROR(B25/E25,"") | H25: =SUMIFS('Данные'!$F:$F,'Данные'!$A:$A,">="&(($E$3-WEEKDAY($E$3,2)+1-7*(WEEKDAY($E$3,2)<7))-7*13),'Данные'!$A:$A,"<"&((($E$3-WEEKDAY($E$3,2)+1-7*(WEEKDAY($E$3,2)<7))-7*13)+6)+1,'Данные'!$B:$B,$B$3) | I25: =IFERROR(B25/H25,"") | J25: =IFERROR(H25/E25,"")
A26: =TEXT((($E$3-WEEKDAY($E$3,2)+1-7*(WEEKDAY($E$3,2)<7))-7*12),"DD.MM")&"–"&TEXT((($E$3-WEEKDAY($E$3,2)+1-7*(WEEKDAY($E$3,2)<7))-7*12)+6,"DD.MM.YYYY") | B26: =SUMIFS('Данные'!$C:$C,'Данные'!$A:$A,">="&(($E$3-WEEKDAY($E$3,2)+1-7*(WEEKDAY($E$3,2)<7))-7*12),'Данные'!$A:$A,"<"&((($E$3-WEEKDAY($E$3,2)+1-7*(WEEKDAY($E$3,2)<7))-7*12)+6)+1,'Данные'!$B:$B,$B$3) | C26: =B26*(100+22)/100 | D26: =SUMIFS('Данные'!$D:$D,'Данные'!$A:$A,">="&(($E$3-WEEKDAY($E$3,2)+1-7*(WEEKDAY($E$3,2)<7))-7*12),'Данные'!$A:$A,"<"&((($E$3-WEEKDAY($E$3,2)+1-7*(WEEKDAY($E$3,2)<7))-7*12)+6)+1,'Данные'!$B:$B,$B$3) | E26: =SUMIFS('Данные'!$E:$E,'Данные'!$A:$A,">="&(($E$3-WEEKDAY($E$3,2)+1-7*(WEEKDAY($E$3,2)<7))-7*12),'Данные'!$A:$A,"<"&((($E$3-WEEKDAY($E$3,2)+1-7*(WEEKDAY($E$3,2)<7))-7*12)+6)+1,'Данные'!$B:$B,$B$3) | F26: =IFERROR(E26/D26,"") | G26: =IFERROR(B26/E26,"") | H26: =SUMIFS('Данные'!$F:$F,'Данные'!$A:$A,">="&(($E$3-WEEKDAY($E$3,2)+1-7*(WEEKDAY($E$3,2)<7))-7*12),'Данные'!$A:$A,"<"&((($E$3-WEEKDAY($E$3,2)+1-7*(WEEKDAY($E$3,2)<7))-7*12)+6)+1,'Данные'!$B:$B,$B$3) | I26: =IFERROR(B26/H26,"") | J26: =IFERROR(H26/E26,"")
A27: =TEXT((($E$3-WEEKDAY($E$3,2)+1-7*(WEEKDAY($E$3,2)<7))-7*11),"DD.MM")&"–"&TEXT((($E$3-WEEKDAY($E$3,2)+1-7*(WEEKDAY($E$3,2)<7))-7*11)+6,"DD.MM.YYYY") | B27: =SUMIFS('Данные'!$C:$C,'Данные'!$A:$A,">="&(($E$3-WEEKDAY($E$3,2)+1-7*(WEEKDAY($E$3,2)<7))-7*11),'Данные'!$A:$A,"<"&((($E$3-WEEKDAY($E$3,2)+1-7*(WEEKDAY($E$3,2)<7))-7*11)+6)+1,'Данные'!$B:$B,$B$3) | C27: =B27*(100+22)/100 | D27: =SUMIFS('Данные'!$D:$D,'Данные'!$A:$A,">="&(($E$3-WEEKDAY($E$3,2)+1-7*(WEEKDAY($E$3,2)<7))-7*11),'Данные'!$A:$A,"<"&((($E$3-WEEKDAY($E$3,2)+1-7*(WEEKDAY($E$3,2)<7))-7*11)+6)+1,'Данные'!$B:$B,$B$3) | E27: =SUMIFS('Данные'!$E:$E,'Данные'!$A:$A,">="&(($E$3-WEEKDAY($E$3,2)+1-7*(WEEKDAY($E$3,2)<7))-7*11),'Данные'!$A:$A,"<"&((($E$3-WEEKDAY($E$3,2)+1-7*(WEEKDAY($E$3,2)<7))-7*11)+6)+1,'Данные'!$B:$B,$B$3) | F27: =IFERROR(E27/D27,"") | G27: =IFERROR(B27/E27,"") | H27: =SUMIFS('Данные'!$F:$F,'Данные'!$A:$A,">="&(($E$3-WEEKDAY($E$3,2)+1-7*(WEEKDAY($E$3,2)<7))-7*11),'Данные'!$A:$A,"<"&((($E$3-WEEKDAY($E$3,2)+1-7*(WEEKDAY($E$3,2)<7))-7*11)+6)+1,'Данные'!$B:$B,$B$3) | I27: =IFERROR(B27/H27,"") | J27: =IFERROR(H27/E27,"")
A28: =TEXT((($E$3-WEEKDAY($E$3,2)+1-7*(WEEKDAY($E$3,2)<7))-7*10),"DD.MM")&"–"&TEXT((($E$3-WEEKDAY($E$3,2)+1-7*(WEEKDAY($E$3,2)<7))-7*10)+6,"DD.MM.YYYY") | B28: =SUMIFS('Данные'!$C:$C,'Данные'!$A:$A,">="&(($E$3-WEEKDAY($E$3,2)+1-7*(WEEKDAY($E$3,2)<7))-7*10),'Данные'!$A:$A,"<"&((($E$3-WEEKDAY($E$3,2)+1-7*(WEEKDAY($E$3,2)<7))-7*10)+6)+1,'Данные'!$B:$B,$B$3) | C28: =B28*(100+22)/100 | D28: =SUMIFS('Данные'!$D:$D,'Данные'!$A:$A,">="&(($E$3-WEEKDAY($E$3,2)+1-7*(WEEKDAY($E$3,2)<7))-7*10),'Данные'!$A:$A,"<"&((($E$3-WEEKDAY($E$3,2)+1-7*(WEEKDAY($E$3,2)<7))-7*10)+6)+1,'Данные'!$B:$B,$B$3) | E28: =SUMIFS('Данные'!$E:$E,'Данные'!$A:$A,">="&(($E$3-WEEKDAY($E$3,2)+1-7*(WEEKDAY($E$3,2)<7))-7*10),'Данные'!$A:$A,"<"&((($E$3-WEEKDAY($E$3,2)+1-7*(WEEKDAY($E$3,2)<7))-7*10)+6)+1,'Данные'!$B:$B,$B$3) | F28: =IFERROR(E28/D28,"") | G28: =IFERROR(B28/E28,"") | H28: =SUMIFS('Данные'!$F:$F,'Данные'!$A:$A,">="&(($E$3-WEEKDAY($E$3,2)+1-7*(WEEKDAY($E$3,2)<7))-7*10),'Данные'!$A:$A,"<"&((($E$3-WEEKDAY($E$3,2)+1-7*(WEEKDAY($E$3,2)<7))-7*10)+6)+1,'Данные'!$B:$B,$B$3) | I28: =IFERROR(B28/H28,"") | J28: =IFERROR(H28/E28,"")
A29: =TEXT((($E$3-WEEKDAY($E$3,2)+1-7*(WEEKDAY($E$3,2)<7))-7*9),"DD.MM")&"–"&TEXT((($E$3-WEEKDAY($E$3,2)+1-7*(WEEKDAY($E$3,2)<7))-7*9)+6,"DD.MM.YYYY") | B29: =SUMIFS('Данные'!$C:$C,'Данные'!$A:$A,">="&(($E$3-WEEKDAY($E$3,2)+1-7*(WEEKDAY($E$3,2)<7))-7*9),'Данные'!$A:$A,"<"&((($E$3-WEEKDAY($E$3,2)+1-7*(WEEKDAY($E$3,2)<7))-7*9)+6)+1,'Данные'!$B:$B,$B$3) | C29: =B29*(100+22)/100 | D29: =SUMIFS('Данные'!$D:$D,'Данные'!$A:$A,">="&(($E$3-WEEKDAY($E$3,2)+1-7*(WEEKDAY($E$3,2)<7))-7*9),'Данные'!$A:$A,"<"&((($E$3-WEEKDAY($E$3,2)+1-7*(WEEKDAY($E$3,2)<7))-7*9)+6)+1,'Данные'!$B:$B,$B$3) | E29: =SUMIFS('Данные'!$E:$E,'Данные'!$A:$A,">="&(($E$3-WEEKDAY($E$3,2)+1-7*(WEEKDAY($E$3,2)<7))-7*9),'Данные'!$A:$A,"<"&((($E$3-WEEKDAY($E$3,2)+1-7*(WEEKDAY($E$3,2)<7))-7*9)+6)+1,'Данные'!$B:$B,$B$3) | F29: =IFERROR(E29/D29,"") | G29: =IFERROR(B29/E29,"") | H29: =SUMIFS('Данные'!$F:$F,'Данные'!$A:$A,">="&(($E$3-WEEKDAY($E$3,2)+1-7*(WEEKDAY($E$3,2)<7))-7*9),'Данные'!$A:$A,"<"&((($E$3-WEEKDAY($E$3,2)+1-7*(WEEKDAY($E$3,2)<7))-7*9)+6)+1,'Данные'!$B:$B,$B$3) | I29: =IFERROR(B29/H29,"") | J29: =IFERROR(H29/E29,"")
A30: =TEXT((($E$3-WEEKDAY($E$3,2)+1-7*(WEEKDAY($E$3,2)<7))-7*8),"DD.MM")&"–"&TEXT((($E$3-WEEKDAY($E$3,2)+1-7*(WEEKDAY($E$3,2)<7))-7*8)+6,"DD.MM.YYYY") | B30: =SUMIFS('Данные'!$C:$C,'Данные'!$A:$A,">="&(($E$3-WEEKDAY($E$3,2)+1-7*(WEEKDAY($E$3,2)<7))-7*8),'Данные'!$A:$A,"<"&((($E$3-WEEKDAY($E$3,2)+1-7*(WEEKDAY($E$3,2)<7))-7*8)+6)+1,'Данные'!$B:$B,$B$3) | C30: =B30*(100+22)/100 | D30: =SUMIFS('Данные'!$D:$D,'Данные'!$A:$A,">="&(($E$3-WEEKDAY($E$3,2)+1-7*(WEEKDAY($E$3,2)<7))-7*8),'Данные'!$A:$A,"<"&((($E$3-WEEKDAY($E$3,2)+1-7*(WEEKDAY($E$3,2)<7))-7*8)+6)+1,'Данные'!$B:$B,$B$3) | E30: =SUMIFS('Данные'!$E:$E,'Данные'!$A:$A,">="&(($E$3-WEEKDAY($E$3,2)+1-7*(WEEKDAY($E$3,2)<7))-7*8),'Данные'!$A:$A,"<"&((($E$3-WEEKDAY($E$3,2)+1-7*(WEEKDAY($E$3,2)<7))-7*8)+6)+1,'Данные'!$B:$B,$B$3) | F30: =IFERROR(E30/D30,"") | G30: =IFERROR(B30/E30,"") | H30: =SUMIFS('Данные'!$F:$F,'Данные'!$A:$A,">="&(($E$3-WEEKDAY($E$3,2)+1-7*(WEEKDAY($E$3,2)<7))-7*8),'Данные'!$A:$A,"<"&((($E$3-WEEKDAY($E$3,2)+1-7*(WEEKDAY($E$3,2)<7))-7*8)+6)+1,'Данные'!$B:$B,$B$3) | I30: =IFERROR(B30/H30,"") | J30: =IFERROR(H30/E30,"")
A31: =TEXT((($E$3-WEEKDAY($E$3,2)+1-7*(WEEKDAY($E$3,2)<7))-7*7),"DD.MM")&"–"&TEXT((($E$3-WEEKDAY($E$3,2)+1-7*(WEEKDAY($E$3,2)<7))-7*7)+6,"DD.MM.YYYY") | B31: =SUMIFS('Данные'!$C:$C,'Данные'!$A:$A,">="&(($E$3-WEEKDAY($E$3,2)+1-7*(WEEKDAY($E$3,2)<7))-7*7),'Данные'!$A:$A,"<"&((($E$3-WEEKDAY($E$3,2)+1-7*(WEEKDAY($E$3,2)<7))-7*7)+6)+1,'Данные'!$B:$B,$B$3) | C31: =B31*(100+22)/100 | D31: =SUMIFS('Данные'!$D:$D,'Данные'!$A:$A,">="&(($E$3-WEEKDAY($E$3,2)+1-7*(WEEKDAY($E$3,2)<7))-7*7),'Данные'!$A:$A,"<"&((($E$3-WEEKDAY($E$3,2)+1-7*(WEEKDAY($E$3,2)<7))-7*7)+6)+1,'Данные'!$B:$B,$B$3) | E31: =SUMIFS('Данные'!$E:$E,'Данные'!$A:$A,">="&(($E$3-WEEKDAY($E$3,2)+1-7*(WEEKDAY($E$3,2)<7))-7*7),'Данные'!$A:$A,"<"&((($E$3-WEEKDAY($E$3,2)+1-7*(WEEKDAY($E$3,2)<7))-7*7)+6)+1,'Данные'!$B:$B,$B$3) | F31: =IFERROR(E31/D31,"") | G31: =IFERROR(B31/E31,"") | H31: =SUMIFS('Данные'!$F:$F,'Данные'!$A:$A,">="&(($E$3-WEEKDAY($E$3,2)+1-7*(WEEKDAY($E$3,2)<7))-7*7),'Данные'!$A:$A,"<"&((($E$3-WEEKDAY($E$3,2)+1-7*(WEEKDAY($E$3,2)<7))-7*7)+6)+1,'Данные'!$B:$B,$B$3) | I31: =IFERROR(B31/H31,"") | J31: =IFERROR(H31/E31,"")
A32: =TEXT((($E$3-WEEKDAY($E$3,2)+1-7*(WEEKDAY($E$3,2)<7))-7*6),"DD.MM")&"–"&TEXT((($E$3-WEEKDAY($E$3,2)+1-7*(WEEKDAY($E$3,2)<7))-7*6)+6,"DD.MM.YYYY") | B32: =SUMIFS('Данные'!$C:$C,'Данные'!$A:$A,">="&(($E$3-WEEKDAY($E$3,2)+1-7*(WEEKDAY($E$3,2)<7))-7*6),'Данные'!$A:$A,"<"&((($E$3-WEEKDAY($E$3,2)+1-7*(WEEKDAY($E$3,2)<7))-7*6)+6)+1,'Данные'!$B:$B,$B$3) | C32: =B32*(100+22)/100 | D32: =SUMIFS('Данные'!$D:$D,'Данные'!$A:$A,">="&(($E$3-WEEKDAY($E$3,2)+1-7*(WEEKDAY($E$3,2)<7))-7*6),'Данные'!$A:$A,"<"&((($E$3-WEEKDAY($E$3,2)+1-7*(WEEKDAY($E$3,2)<7))-7*6)+6)+1,'Данные'!$B:$B,$B$3) | E32: =SUMIFS('Данные'!$E:$E,'Данные'!$A:$A,">="&(($E$3-WEEKDAY($E$3,2)+1-7*(WEEKDAY($E$3,2)<7))-7*6),'Данные'!$A:$A,"<"&((($E$3-WEEKDAY($E$3,2)+1-7*(WEEKDAY($E$3,2)<7))-7*6)+6)+1,'Данные'!$B:$B,$B$3) | F32: =IFERROR(E32/D32,"") | G32: =IFERROR(B32/E32,"") | H32: =SUMIFS('Данные'!$F:$F,'Данные'!$A:$A,">="&(($E$3-WEEKDAY($E$3,2)+1-7*(WEEKDAY($E$3,2)<7))-7*6),'Данные'!$A:$A,"<"&((($E$3-WEEKDAY($E$3,2)+1-7*(WEEKDAY($E$3,2)<7))-7*6)+6)+1,'Данные'!$B:$B,$B$3) | I32: =IFERROR(B32/H32,"") | J32: =IFERROR(H32/E32,"")
A33: =TEXT((($E$3-WEEKDAY($E$3,2)+1-7*(WEEKDAY($E$3,2)<7))-7*5),"DD.MM")&"–"&TEXT((($E$3-WEEKDAY($E$3,2)+1-7*(WEEKDAY($E$3,2)<7))-7*5)+6,"DD.MM.YYYY") | B33: =SUMIFS('Данные'!$C:$C,'Данные'!$A:$A,">="&(($E$3-WEEKDAY($E$3,2)+1-7*(WEEKDAY($E$3,2)<7))-7*5),'Данные'!$A:$A,"<"&((($E$3-WEEKDAY($E$3,2)+1-7*(WEEKDAY($E$3,2)<7))-7*5)+6)+1,'Данные'!$B:$B,$B$3) | C33: =B33*(100+22)/100 | D33: =SUMIFS('Данные'!$D:$D,'Данные'!$A:$A,">="&(($E$3-WEEKDAY($E$3,2)+1-7*(WEEKDAY($E$3,2)<7))-7*5),'Данные'!$A:$A,"<"&((($E$3-WEEKDAY($E$3,2)+1-7*(WEEKDAY($E$3,2)<7))-7*5)+6)+1,'Данные'!$B:$B,$B$3) | E33: =SUMIFS('Данные'!$E:$E,'Данные'!$A:$A,">="&(($E$3-WEEKDAY($E$3,2)+1-7*(WEEKDAY($E$3,2)<7))-7*5),'Данные'!$A:$A,"<"&((($E$3-WEEKDAY($E$3,2)+1-7*(WEEKDAY($E$3,2)<7))-7*5)+6)+1,'Данные'!$B:$B,$B$3) | F33: =IFERROR(E33/D33,"") | G33: =IFERROR(B33/E33,"") | H33: =SUMIFS('Данные'!$F:$F,'Данные'!$A:$A,">="&(($E$3-WEEKDAY($E$3,2)+1-7*(WEEKDAY($E$3,2)<7))-7*5),'Данные'!$A:$A,"<"&((($E$3-WEEKDAY($E$3,2)+1-7*(WEEKDAY($E$3,2)<7))-7*5)+6)+1,'Данные'!$B:$B,$B$3) | I33: =IFERROR(B33/H33,"") | J33: =IFERROR(H33/E33,"")
A34: =TEXT((($E$3-WEEKDAY($E$3,2)+1-7*(WEEKDAY($E$3,2)<7))-7*4),"DD.MM")&"–"&TEXT((($E$3-WEEKDAY($E$3,2)+1-7*(WEEKDAY($E$3,2)<7))-7*4)+6,"DD.MM.YYYY") | B34: =SUMIFS('Данные'!$C:$C,'Данные'!$A:$A,">="&(($E$3-WEEKDAY($E$3,2)+1-7*(WEEKDAY($E$3,2)<7))-7*4),'Данные'!$A:$A,"<"&((($E$3-WEEKDAY($E$3,2)+1-7*(WEEKDAY($E$3,2)<7))-7*4)+6)+1,'Данные'!$B:$B,$B$3) | C34: =B34*(100+22)/100 | D34: =SUMIFS('Данные'!$D:$D,'Данные'!$A:$A,">="&(($E$3-WEEKDAY($E$3,2)+1-7*(WEEKDAY($E$3,2)<7))-7*4),'Данные'!$A:$A,"<"&((($E$3-WEEKDAY($E$3,2)+1-7*(WEEKDAY($E$3,2)<7))-7*4)+6)+1,'Данные'!$B:$B,$B$3) | E34: =SUMIFS('Данные'!$E:$E,'Данные'!$A:$A,">="&(($E$3-WEEKDAY($E$3,2)+1-7*(WEEKDAY($E$3,2)<7))-7*4),'Данные'!$A:$A,"<"&((($E$3-WEEKDAY($E$3,2)+1-7*(WEEKDAY($E$3,2)<7))-7*4)+6)+1,'Данные'!$B:$B,$B$3) | F34: =IFERROR(E34/D34,"") | G34: =IFERROR(B34/E34,"") | H34: =SUMIFS('Данные'!$F:$F,'Данные'!$A:$A,">="&(($E$3-WEEKDAY($E$3,2)+1-7*(WEEKDAY($E$3,2)<7))-7*4),'Данные'!$A:$A,"<"&((($E$3-WEEKDAY($E$3,2)+1-7*(WEEKDAY($E$3,2)<7))-7*4)+6)+1,'Данные'!$B:$B,$B$3) | I34: =IFERROR(B34/H34,"") | J34: =IFERROR(H34/E34,"")
A35: =TEXT((($E$3-WEEKDAY($E$3,2)+1-7*(WEEKDAY($E$3,2)<7))-7*3),"DD.MM")&"–"&TEXT((($E$3-WEEKDAY($E$3,2)+1-7*(WEEKDAY($E$3,2)<7))-7*3)+6,"DD.MM.YYYY") | B35: =SUMIFS('Данные'!$C:$C,'Данные'!$A:$A,">="&(($E$3-WEEKDAY($E$3,2)+1-7*(WEEKDAY($E$3,2)<7))-7*3),'Данные'!$A:$A,"<"&((($E$3-WEEKDAY($E$3,2)+1-7*(WEEKDAY($E$3,2)<7))-7*3)+6)+1,'Данные'!$B:$B,$B$3) | C35: =B35*(100+22)/100 | D35: =SUMIFS('Данные'!$D:$D,'Данные'!$A:$A,">="&(($E$3-WEEKDAY($E$3,2)+1-7*(WEEKDAY($E$3,2)<7))-7*3),'Данные'!$A:$A,"<"&((($E$3-WEEKDAY($E$3,2)+1-7*(WEEKDAY($E$3,2)<7))-7*3)+6)+1,'Данные'!$B:$B,$B$3) | E35: =SUMIFS('Данные'!$E:$E,'Данные'!$A:$A,">="&(($E$3-WEEKDAY($E$3,2)+1-7*(WEEKDAY($E$3,2)<7))-7*3),'Данные'!$A:$A,"<"&((($E$3-WEEKDAY($E$3,2)+1-7*(WEEKDAY($E$3,2)<7))-7*3)+6)+1,'Данные'!$B:$B,$B$3) | F35: =IFERROR(E35/D35,"") | G35: =IFERROR(B35/E35,"") | H35: =SUMIFS('Данные'!$F:$F,'Данные'!$A:$A,">="&(($E$3-WEEKDAY($E$3,2)+1-7*(WEEKDAY($E$3,2)<7))-7*3),'Данные'!$A:$A,"<"&((($E$3-WEEKDAY($E$3,2)+1-7*(WEEKDAY($E$3,2)<7))-7*3)+6)+1,'Данные'!$B:$B,$B$3) | I35: =IFERROR(B35/H35,"") | J35: =IFERROR(H35/E35,"")
A36: =TEXT((($E$3-WEEKDAY($E$3,2)+1-7*(WEEKDAY($E$3,2)<7))-7*2),"DD.MM")&"–"&TEXT((($E$3-WEEKDAY($E$3,2)+1-7*(WEEKDAY($E$3,2)<7))-7*2)+6,"DD.MM.YYYY") | B36: =SUMIFS('Данные'!$C:$C,'Данные'!$A:$A,">="&(($E$3-WEEKDAY($E$3,2)+1-7*(WEEKDAY($E$3,2)<7))-7*2),'Данные'!$A:$A,"<"&((($E$3-WEEKDAY($E$3,2)+1-7*(WEEKDAY($E$3,2)<7))-7*2)+6)+1,'Данные'!$B:$B,$B$3) | C36: =B36*(100+22)/100 | D36: =SUMIFS('Данные'!$D:$D,'Данные'!$A:$A,">="&(($E$3-WEEKDAY($E$3,2)+1-7*(WEEKDAY($E$3,2)<7))-7*2),'Данные'!$A:$A,"<"&((($E$3-WEEKDAY($E$3,2)+1-7*(WEEKDAY($E$3,2)<7))-7*2)+6)+1,'Данные'!$B:$B,$B$3) | E36: =SUMIFS('Данные'!$E:$E,'Данные'!$A:$A,">="&(($E$3-WEEKDAY($E$3,2)+1-7*(WEEKDAY($E$3,2)<7))-7*2),'Данные'!$A:$A,"<"&((($E$3-WEEKDAY($E$3,2)+1-7*(WEEKDAY($E$3,2)<7))-7*2)+6)+1,'Данные'!$B:$B,$B$3) | F36: =IFERROR(E36/D36,"") | G36: =IFERROR(B36/E36,"") | H36: =SUMIFS('Данные'!$F:$F,'Данные'!$A:$A,">="&(($E$3-WEEKDAY($E$3,2)+1-7*(WEEKDAY($E$3,2)<7))-7*2),'Данные'!$A:$A,"<"&((($E$3-WEEKDAY($E$3,2)+1-7*(WEEKDAY($E$3,2)<7))-7*2)+6)+1,'Данные'!$B:$B,$B$3) | I36: =IFERROR(B36/H36,"") | J36: =IFERROR(H36/E36,"")
A37: =TEXT((($E$3-WEEKDAY($E$3,2)+1-7*(WEEKDAY($E$3,2)<7))-7*1),"DD.MM")&"–"&TEXT((($E$3-WEEKDAY($E$3,2)+1-7*(WEEKDAY($E$3,2)<7))-7*1)+6,"DD.MM.YYYY") | B37: =SUMIFS('Данные'!$C:$C,'Данные'!$A:$A,">="&(($E$3-WEEKDAY($E$3,2)+1-7*(WEEKDAY($E$3,2)<7))-7*1),'Данные'!$A:$A,"<"&((($E$3-WEEKDAY($E$3,2)+1-7*(WEEKDAY($E$3,2)<7))-7*1)+6)+1,'Данные'!$B:$B,$B$3) | C37: =B37*(100+22)/100 | D37: =SUMIFS('Данные'!$D:$D,'Данные'!$A:$A,">="&(($E$3-WEEKDAY($E$3,2)+1-7*(WEEKDAY($E$3,2)<7))-7*1),'Данные'!$A:$A,"<"&((($E$3-WEEKDAY($E$3,2)+1-7*(WEEKDAY($E$3,2)<7))-7*1)+6)+1,'Данные'!$B:$B,$B$3) | E37: =SUMIFS('Данные'!$E:$E,'Данные'!$A:$A,">="&(($E$3-WEEKDAY($E$3,2)+1-7*(WEEKDAY($E$3,2)<7))-7*1),'Данные'!$A:$A,"<"&((($E$3-WEEKDAY($E$3,2)+1-7*(WEEKDAY($E$3,2)<7))-7*1)+6)+1,'Данные'!$B:$B,$B$3) | F37: =IFERROR(E37/D37,"") | G37: =IFERROR(B37/E37,"") | H37: =SUMIFS('Данные'!$F:$F,'Данные'!$A:$A,">="&(($E$3-WEEKDAY($E$3,2)+1-7*(WEEKDAY($E$3,2)<7))-7*1),'Данные'!$A:$A,"<"&((($E$3-WEEKDAY($E$3,2)+1-7*(WEEKDAY($E$3,2)<7))-7*1)+6)+1,'Данные'!$B:$B,$B$3) | I37: =IFERROR(B37/H37,"") | J37: =IFERROR(H37/E37,"")
A38: =TEXT((($E$3-WEEKDAY($E$3,2)+1-7*(WEEKDAY($E$3,2)<7))-7*0),"DD.MM")&"–"&TEXT((($E$3-WEEKDAY($E$3,2)+1-7*(WEEKDAY($E$3,2)<7))-7*0)+6,"DD.MM.YYYY") | B38: =SUMIFS('Данные'!$C:$C,'Данные'!$A:$A,">="&(($E$3-WEEKDAY($E$3,2)+1-7*(WEEKDAY($E$3,2)<7))-7*0),'Данные'!$A:$A,"<"&((($E$3-WEEKDAY($E$3,2)+1-7*(WEEKDAY($E$3,2)<7))-7*0)+6)+1,'Данные'!$B:$B,$B$3) | C38: =B38*(100+22)/100 | D38: =SUMIFS('Данные'!$D:$D,'Данные'!$A:$A,">="&(($E$3-WEEKDAY($E$3,2)+1-7*(WEEKDAY($E$3,2)<7))-7*0),'Данные'!$A:$A,"<"&((($E$3-WEEKDAY($E$3,2)+1-7*(WEEKDAY($E$3,2)<7))-7*0)+6)+1,'Данные'!$B:$B,$B$3) | E38: =SUMIFS('Данные'!$E:$E,'Данные'!$A:$A,">="&(($E$3-WEEKDAY($E$3,2)+1-7*(WEEKDAY($E$3,2)<7))-7*0),'Данные'!$A:$A,"<"&((($E$3-WEEKDAY($E$3,2)+1-7*(WEEKDAY($E$3,2)<7))-7*0)+6)+1,'Данные'!$B:$B,$B$3) | F38: =IFERROR(E38/D38,"") | G38: =IFERROR(B38/E38,"") | H38: =SUMIFS('Данные'!$F:$F,'Данные'!$A:$A,">="&(($E$3-WEEKDAY($E$3,2)+1-7*(WEEKDAY($E$3,2)<7))-7*0),'Данные'!$A:$A,"<"&((($E$3-WEEKDAY($E$3,2)+1-7*(WEEKDAY($E$3,2)<7))-7*0)+6)+1,'Данные'!$B:$B,$B$3) | I38: =IFERROR(B38/H38,"") | J38: =IFERROR(H38/E38,"")
A39: Разница с прошлой неделей | B39: =IFERROR(B38/B37-1,"") | C39: =IFERROR(C38/C37-1,"") | D39: =IFERROR(D38/D37-1,"") | E39: =IFERROR(E38/E37-1,"") | F39: =IFERROR(F38/F37-1,"") | G39: =IFERROR(G38/G37-1,"") | H39: =IFERROR(H38/H37-1,"") | I39: =IFERROR(I38/I37-1,"") | J39: =IFERROR(J38/J37-1,"")
A41: 📅 По завершённым месяцам (12)
A42: Месяц | B42: Расход | C42: Расход с НДС | D42: Показы | E42: Клики | F42: CTR | G42: CPC | H42: Подписки | I42: Цена подписки | J42: CR в подписку
...

Sheet Направление 2
A1: ="Сова · "&$B$3
A2: ="Итоги всех кампаний кабинета VK Реклама · данные по "&TEXT($E$3,"DD.MM.YYYY")
A3: Направление | B3: ='⚙ Настройки'!$A$3 | D3: Данные по | E3: ='⚙ Настройки'!$B$7 | G3: Период с | I3: по | N3: 📈 Подписки и расход по дням за период выше
H4: =IF(AND(ISNUMBER(H3),ISNUMBER(J3),H3>J3),"⚠ Дата «с» позже даты «по»",IF(OR(ISNUMBER(H3),ISNUMBER(J3)),"Сравнение — с предыдущим периодом той же длины. Очистите поля, чтобы вернуть текущий месяц.","Пусто — текущий месяц. Дату выбирают двойным щелчком."))
A5: =IF(OR(ISNUMBER($H$3),ISNUMBER($J$3)),"Выбранный период против предыдущего той же длины","Этот месяц против тех же дней прошлого")
A6: Период | B6: Расход | C6: Расход с НДС | D6: Показы | E6: Клики | F6: CTR | G6: CPC | H6: Подписки | I6: Цена подписки | J6: CR в подписку | K6: с | L6: по
A7: =IF(OR(ISNUMBER($H$3),ISNUMBER($J$3)),"Выбранный период","Этот месяц") | B7: =SUMIFS('Данные'!$C:$C,'Данные'!$A:$A,">="&$K$7,'Данные'!$A:$A,"<"&$L$7+1,'Данные'!$B:$B,$B$3) | C7: =B7*(100+22)/100 | D7: =SUMIFS('Данные'!$D:$D,'Данные'!$A:$A,">="&$K$7,'Данные'!$A:$A,"<"&$L$7+1,'Данные'!$B:$B,$B$3) | E7: =SUMIFS('Данные'!$E:$E,'Данные'!$A:$A,">="&$K$7,'Данные'!$A:$A,"<"&$L$7+1,'Данные'!$B:$B,$B$3) | F7: =IFERROR(E7/D7,"") | G7: =IFERROR(B7/E7,"") | H7: =SUMIFS('Данные'!$F:$F,'Данные'!$A:$A,">="&$K$7,'Данные'!$A:$A,"<"&$L$7+1,'Данные'!$B:$B,$B$3) | I7: =IFERROR(B7/H7,"") | J7: =IFERROR(H7/E7,"") | K7: =IF(ISNUMBER($H$3),$H$3,DATE(YEAR(L7),MONTH(L7),1)) | L7: =IF(ISNUMBER($J$3),$J$3,$E$3)
A8: =IF(OR(ISNUMBER($H$3),ISNUMBER($J$3)),"Предыдущий, той же длины","Прошлый, те же дни") | B8: =SUMIFS('Данные'!$C:$C,'Данные'!$A:$A,">="&$K$8,'Данные'!$A:$A,"<"&$L$8+1,'Данные'!$B:$B,$B$3) | C8: =B8*(100+22)/100 | D8: =SUMIFS('Данные'!$D:$D,'Данные'!$A:$A,">="&$K$8,'Данные'!$A:$A,"<"&$L$8+1,'Данные'!$B:$B,$B$3) | E8: =SUMIFS('Данные'!$E:$E,'Данные'!$A:$A,">="&$K$8,'Данные'!$A:$A,"<"&$L$8+1,'Данные'!$B:$B,$B$3) | F8: =IFERROR(E8/D8,"") | G8: =IFERROR(B8/E8,"") | H8: =SUMIFS('Данные'!$F:$F,'Данные'!$A:$A,">="&$K$8,'Данные'!$A:$A,"<"&$L$8+1,'Данные'!$B:$B,$B$3) | I8: =IFERROR(B8/H8,"") | J8: =IFERROR(H8/E8,"") | K8: =IF(OR(ISNUMBER($H$3),ISNUMBER($J$3)),2*K7-L7-1,EDATE(K7,-1)) | L8: =IF(OR(ISNUMBER($H$3),ISNUMBER($J$3)),K7-1,EDATE(L7,-1))
A9: Изменение | B9: =IFERROR(B7/B8-1,"") | C9: =IFERROR(C7/C8-1,"") | D9: =IFERROR(D7/D8-1,"") | E9: =IFERROR(E7/E8-1,"") | F9: =IFERROR(F7/F8-1,"") | G9: =IFERROR(G7/G8-1,"") | H9: =IFERROR(H7/H8-1,"") | I9: =IFERROR(I7/I8-1,"") | J9: =IFERROR(J7/J8-1,"")
A11: 🗓 По завершённым неделям (26)
A12: Неделя | B12: Расход | C12: Расход с НДС | D12: Показы | E12: Клики | F12: CTR | G12: CPC | H12: Подписки | I12: Цена подписки | J12: CR в подписку
A13: =TEXT((($E$3-WEEKDAY($E$3,2)+1-7*(WEEKDAY($E$3,2)<7))-7*25),"DD.MM")&"–"&TEXT((($E$3-WEEKDAY($E$3,2)+1-7*(WEEKDAY($E$3,2)<7))-7*25)+6,"DD.MM.YYYY") | B13: =SUMIFS('Данные'!$C:$C,'Данные'!$A:$A,">="&(($E$3-WEEKDAY($E$3,2)+1-7*(WEEKDAY($E$3,2)<7))-7*25),'Данные'!$A:$A,"<"&((($E$3-WEEKDAY($E$3,2)+1-7*(WEEKDAY($E$3,2)<7))-7*25)+6)+1,'Данные'!$B:$B,$B$3) | C13: =B13*(100+22)/100 | D13: =SUMIFS('Данные'!$D:$D,'Данные'!$A:$A,">="&(($E$3-WEEKDAY($E$3,2)+1-7*(WEEKDAY($E$3,2)<7))-7*25),'Данные'!$A:$A,"<"&((($E$3-WEEKDAY($E$3,2)+1-7*(WEEKDAY($E$3,2)<7))-7*25)+6)+1,'Данные'!$B:$B,$B$3) | E13: =SUMIFS('Данные'!$E:$E,'Данные'!$A:$A,">="&(($E$3-WEEKDAY($E$3,2)+1-7*(WEEKDAY($E$3,2)<7))-7*25),'Данные'!$A:$A,"<"&((($E$3-WEEKDAY($E$3,2)+1-7*(WEEKDAY($E$3,2)<7))-7*25)+6)+1,'Данные'!$B:$B,$B$3) | F13: =IFERROR(E13/D13,"") | G13: =IFERROR(B13/E13,"") | H13: =SUMIFS('Данные'!$F:$F,'Данные'!$A:$A,">="&(($E$3-WEEKDAY($E$3,2)+1-7*(WEEKDAY($E$3,2)<7))-7*25),'Данные'!$A:$A,"<"&((($E$3-WEEKDAY($E$3,2)+1-7*(WEEKDAY($E$3,2)<7))-7*25)+6)+1,'Данные'!$B:$B,$B$3) | I13: =IFERROR(B13/H13,"") | J13: =IFERROR(H13/E13,"")
